Running operations
Got op {'op': 'login'}
Server started http://localhost:8080
Adding url
Got op {'op': 'add_recipe', 'params': {'url': 'https://www.allrecipes.com/recipe/244447/two-ingredient-pizza-dough/'}}
Servings 8
| Searching for Ingredient(count=1.5, unit='cups', ingredient='self-rising flour')
| Searching for Ingredient(count=1.0, unit='cup', ingredient='plain Greek yogurt')
| Searching for Ingredient(count=None, unit=None, ingredient='cooking spray')
| Adding Ingredient(count=1.5, unit='cups', ingredient='self-rising flour')
| Getting links 1.0030958652496338
| Adding Ingredient(count=1.0, unit='cup', ingredient='plain Greek yogurt')
| Getting links 0.7695951461791992
Server stopped.
Traceback (most recent call last):
  File "/Library/Frameworks/Python.framework/Versions/3.9/lib/python3.9/site-packages/urllib3/connectionpool.py", line 699, in urlopen
    httplib_response = self._make_request(
  File "/Library/Frameworks/Python.framework/Versions/3.9/lib/python3.9/site-packages/urllib3/connectionpool.py", line 445, in _make_request
    six.raise_from(e, None)
  File "<string>", line 3, in raise_from
  File "/Library/Frameworks/Python.framework/Versions/3.9/lib/python3.9/site-packages/urllib3/connectionpool.py", line 440, in _make_request
    httplib_response = conn.getresponse()
  File "/Library/Frameworks/Python.framework/Versions/3.9/lib/python3.9/http/client.py", line 1377, in getresponse
    response.begin()
  File "/Library/Frameworks/Python.framework/Versions/3.9/lib/python3.9/http/client.py", line 320, in begin
    version, status, reason = self._read_status()
  File "/Library/Frameworks/Python.framework/Versions/3.9/lib/python3.9/http/client.py", line 289, in _read_status
    raise RemoteDisconnected("Remote end closed connection without"
http.client.RemoteDisconnected: Remote end closed connection without response

During handling of the above exception, another exception occurred:

Traceback (most recent call last):
  File "/Users/nathanrush/feast-monorepo/backend/Cart.py", line 186, in _add_ingredient
    added_ingredient = self._add_ingredient_on_page(ingredient_link.link, ingredient)
  File "/Users/nathanrush/feast-monorepo/backend/Cart.py", line 259, in _add_ingredient_on_page
    self.driver.get(link)
  File "/Library/Frameworks/Python.framework/Versions/3.9/lib/python3.9/site-packages/selenium/webdriver/remote/webdriver.py", line 436, in get
    self.execute(Command.GET, {'url': url})
  File "/Library/Frameworks/Python.framework/Versions/3.9/lib/python3.9/site-packages/selenium/webdriver/remote/webdriver.py", line 422, in execute
    response = self.command_executor.execute(driver_command, params)
  File "/Library/Frameworks/Python.framework/Versions/3.9/lib/python3.9/site-packages/selenium/webdriver/remote/remote_connection.py", line 421, in execute
    return self._request(command_info[0], url, body=data)
  File "/Library/Frameworks/Python.framework/Versions/3.9/lib/python3.9/site-packages/selenium/webdriver/remote/remote_connection.py", line 443, in _request
    resp = self._conn.request(method, url, body=body, headers=headers)
  File "/Library/Frameworks/Python.framework/Versions/3.9/lib/python3.9/site-packages/urllib3/request.py", line 78, in request
    return self.request_encode_body(
  File "/Library/Frameworks/Python.framework/Versions/3.9/lib/python3.9/site-packages/urllib3/request.py", line 170, in request_encode_body
    return self.urlopen(method, url, **extra_kw)
  File "/Library/Frameworks/Python.framework/Versions/3.9/lib/python3.9/site-packages/urllib3/poolmanager.py", line 375, in urlopen
    response = conn.urlopen(method, u.request_uri, **kw)
  File "/Library/Frameworks/Python.framework/Versions/3.9/lib/python3.9/site-packages/urllib3/connectionpool.py", line 755, in urlopen
    retries = retries.increment(
  File "/Library/Frameworks/Python.framework/Versions/3.9/lib/python3.9/site-packages/urllib3/util/retry.py", line 532, in increment
    raise six.reraise(type(error), error, _stacktrace)
  File "/Library/Frameworks/Python.framework/Versions/3.9/lib/python3.9/site-packages/urllib3/packages/six.py", line 769, in reraise
    raise value.with_traceback(tb)
  File "/Library/Frameworks/Python.framework/Versions/3.9/lib/python3.9/site-packages/urllib3/connectionpool.py", line 699, in urlopen
    httplib_response = self._make_request(
  File "/Library/Frameworks/Python.framework/Versions/3.9/lib/python3.9/site-packages/urllib3/connectionpool.py", line 445, in _make_request
    six.raise_from(e, None)
  File "<string>", line 3, in raise_from
  File "/Library/Frameworks/Python.framework/Versions/3.9/lib/python3.9/site-packages/urllib3/connectionpool.py", line 440, in _make_request
    httplib_response = conn.getresponse()
  File "/Library/Frameworks/Python.framework/Versions/3.9/lib/python3.9/http/client.py", line 1377, in getresponse
    response.begin()
  File "/Library/Frameworks/Python.framework/Versions/3.9/lib/python3.9/http/client.py", line 320, in begin
    version, status, reason = self._read_status()
  File "/Library/Frameworks/Python.framework/Versions/3.9/lib/python3.9/http/client.py", line 289, in _read_status
    raise RemoteDisconnected("Remote end closed connection without"
urllib3.exceptions.ProtocolError: ('Connection aborted.', RemoteDisconnected('Remote end closed connection without response'))

Traceback (most recent call last):
  File "/Library/Frameworks/Python.framework/Versions/3.9/lib/python3.9/site-packages/urllib3/connection.py", line 174, in _new_conn
    conn = connection.create_connection(
  File "/Library/Frameworks/Python.framework/Versions/3.9/lib/python3.9/site-packages/urllib3/util/connection.py", line 96, in create_connection
    raise err
  File "/Library/Frameworks/Python.framework/Versions/3.9/lib/python3.9/site-packages/urllib3/util/connection.py", line 86, in create_connection
    sock.connect(sa)
ConnectionRefusedError: [Errno 61] Connection refused

During handling of the above exception, another exception occurred:

Traceback (most recent call last):
  File "/Library/Frameworks/Python.framework/Versions/3.9/lib/python3.9/site-packages/urllib3/connectionpool.py", line 699, in urlopen
    httplib_response = self._make_request(
  File "/Library/Frameworks/Python.framework/Versions/3.9/lib/python3.9/site-packages/urllib3/connectionpool.py", line 394, in _make_request
    conn.request(method, url, **httplib_request_kw)
  File "/Library/Frameworks/Python.framework/Versions/3.9/lib/python3.9/site-packages/urllib3/connection.py", line 239, in request
    super(HTTPConnection, self).request(method, url, body=body, headers=headers)
  File "/Library/Frameworks/Python.framework/Versions/3.9/lib/python3.9/http/client.py", line 1285, in request
    self._send_request(method, url, body, headers, encode_chunked)
  File "/Library/Frameworks/Python.framework/Versions/3.9/lib/python3.9/http/client.py", line 1331, in _send_request
    self.endheaders(body, encode_chunked=encode_chunked)
  File "/Library/Frameworks/Python.framework/Versions/3.9/lib/python3.9/http/client.py", line 1280, in endheaders
    self._send_output(message_body, encode_chunked=encode_chunked)
  File "/Library/Frameworks/Python.framework/Versions/3.9/lib/python3.9/http/client.py", line 1040, in _send_output
    self.send(msg)
  File "/Library/Frameworks/Python.framework/Versions/3.9/lib/python3.9/http/client.py", line 980, in send
    self.connect()
  File "/Library/Frameworks/Python.framework/Versions/3.9/lib/python3.9/site-packages/urllib3/connection.py", line 205, in connect
    conn = self._new_conn()
  File "/Library/Frameworks/Python.framework/Versions/3.9/lib/python3.9/site-packages/urllib3/connection.py", line 186, in _new_conn
    raise NewConnectionError(
urllib3.exceptions.NewConnectionError: <urllib3.connection.HTTPConnection object at 0x102e33250>: Failed to establish a new connection: [Errno 61] Connection refused

During handling of the above exception, another exception occurred:

Traceback (most recent call last):
  File "/Users/nathanrush/feast-monorepo/backend/Cart.py", line 186, in _add_ingredient
    added_ingredient = self._add_ingredient_on_page(ingredient_link.link, ingredient)
  File "/Users/nathanrush/feast-monorepo/backend/Cart.py", line 259, in _add_ingredient_on_page
    self.driver.get(link)
  File "/Library/Frameworks/Python.framework/Versions/3.9/lib/python3.9/site-packages/selenium/webdriver/remote/webdriver.py", line 436, in get
    self.execute(Command.GET, {'url': url})
  File "/Library/Frameworks/Python.framework/Versions/3.9/lib/python3.9/site-packages/selenium/webdriver/remote/webdriver.py", line 422, in execute
    response = self.command_executor.execute(driver_command, params)
  File "/Library/Frameworks/Python.framework/Versions/3.9/lib/python3.9/site-packages/selenium/webdriver/remote/remote_connection.py", line 421, in execute
    return self._request(command_info[0], url, body=data)
  File "/Library/Frameworks/Python.framework/Versions/3.9/lib/python3.9/site-packages/selenium/webdriver/remote/remote_connection.py", line 443, in _request
    resp = self._conn.request(method, url, body=body, headers=headers)
  File "/Library/Frameworks/Python.framework/Versions/3.9/lib/python3.9/site-packages/urllib3/request.py", line 78, in request
    return self.request_encode_body(
  File "/Library/Frameworks/Python.framework/Versions/3.9/lib/python3.9/site-packages/urllib3/request.py", line 170, in request_encode_body
    return self.urlopen(method, url, **extra_kw)
  File "/Library/Frameworks/Python.framework/Versions/3.9/lib/python3.9/site-packages/urllib3/poolmanager.py", line 375, in urlopen
    response = conn.urlopen(method, u.request_uri, **kw)
  File "/Library/Frameworks/Python.framework/Versions/3.9/lib/python3.9/site-packages/urllib3/connectionpool.py", line 783, in urlopen
    return self.urlopen(
  File "/Library/Frameworks/Python.framework/Versions/3.9/lib/python3.9/site-packages/urllib3/connectionpool.py", line 783, in urlopen
    return self.urlopen(
  File "/Library/Frameworks/Python.framework/Versions/3.9/lib/python3.9/site-packages/urllib3/connectionpool.py", line 783, in urlopen
    return self.urlopen(
  File "/Library/Frameworks/Python.framework/Versions/3.9/lib/python3.9/site-packages/urllib3/connectionpool.py", line 755, in urlopen
    retries = retries.increment(
  File "/Library/Frameworks/Python.framework/Versions/3.9/lib/python3.9/site-packages/urllib3/util/retry.py", line 574, in increment
    raise MaxRetryError(_pool, url, error or ResponseError(cause))
urllib3.exceptions.MaxRetryError: HTTPConnectionPool(host='localhost', port=63523): Max retries exceeded with url: /session/c57442b967fbcf49e513a96fb69780d5/url (Caused by NewConnectionError('<urllib3.connection.HTTPConnection object at 0x102e33250>: Failed to establish a new connection: [Errno 61] Connection refused'))

Traceback (most recent call last):
  File "/Library/Frameworks/Python.framework/Versions/3.9/lib/python3.9/site-packages/urllib3/connection.py", line 174, in _new_conn
    conn = connection.create_connection(
  File "/Library/Frameworks/Python.framework/Versions/3.9/lib/python3.9/site-packages/urllib3/util/connection.py", line 96, in create_connection
    raise err
  File "/Library/Frameworks/Python.framework/Versions/3.9/lib/python3.9/site-packages/urllib3/util/connection.py", line 86, in create_connection
    sock.connect(sa)
ConnectionRefusedError: [Errno 61] Connection refused

During handling of the above exception, another exception occurred:

Traceback (most recent call last):
  File "/Library/Frameworks/Python.framework/Versions/3.9/lib/python3.9/site-packages/urllib3/connectionpool.py", line 699, in urlopen
    httplib_response = self._make_request(
  File "/Library/Frameworks/Python.framework/Versions/3.9/lib/python3.9/site-packages/urllib3/connectionpool.py", line 394, in _make_request
    conn.request(method, url, **httplib_request_kw)
  File "/Library/Frameworks/Python.framework/Versions/3.9/lib/python3.9/site-packages/urllib3/connection.py", line 239, in request
    super(HTTPConnection, self).request(method, url, body=body, headers=headers)
  File "/Library/Frameworks/Python.framework/Versions/3.9/lib/python3.9/http/client.py", line 1285, in request
    self._send_request(method, url, body, headers, encode_chunked)
  File "/Library/Frameworks/Python.framework/Versions/3.9/lib/python3.9/http/client.py", line 1331, in _send_request
    self.endheaders(body, encode_chunked=encode_chunked)
  File "/Library/Frameworks/Python.framework/Versions/3.9/lib/python3.9/http/client.py", line 1280, in endheaders
    self._send_output(message_body, encode_chunked=encode_chunked)
  File "/Library/Frameworks/Python.framework/Versions/3.9/lib/python3.9/http/client.py", line 1040, in _send_output
    self.send(msg)
  File "/Library/Frameworks/Python.framework/Versions/3.9/lib/python3.9/http/client.py", line 980, in send
    self.connect()
  File "/Library/Frameworks/Python.framework/Versions/3.9/lib/python3.9/site-packages/urllib3/connection.py", line 205, in connect
    conn = self._new_conn()
  File "/Library/Frameworks/Python.framework/Versions/3.9/lib/python3.9/site-packages/urllib3/connection.py", line 186, in _new_conn
    raise NewConnectionError(
urllib3.exceptions.NewConnectionError: <urllib3.connection.HTTPConnection object at 0x102e36040>: Failed to establish a new connection: [Errno 61] Connection refused

During handling of the above exception, another exception occurred:

Traceback (most recent call last):
  File "/Users/nathanrush/feast-monorepo/backend/Cart.py", line 186, in _add_ingredient
    added_ingredient = self._add_ingredient_on_page(ingredient_link.link, ingredient)
  File "/Users/nathanrush/feast-monorepo/backend/Cart.py", line 259, in _add_ingredient_on_page
    self.driver.get(link)
  File "/Library/Frameworks/Python.framework/Versions/3.9/lib/python3.9/site-packages/selenium/webdriver/remote/webdriver.py", line 436, in get
    self.execute(Command.GET, {'url': url})
  File "/Library/Frameworks/Python.framework/Versions/3.9/lib/python3.9/site-packages/selenium/webdriver/remote/webdriver.py", line 422, in execute
    response = self.command_executor.execute(driver_command, params)
  File "/Library/Frameworks/Python.framework/Versions/3.9/lib/python3.9/site-packages/selenium/webdriver/remote/remote_connection.py", line 421, in execute
    return self._request(command_info[0], url, body=data)
  File "/Library/Frameworks/Python.framework/Versions/3.9/lib/python3.9/site-packages/selenium/webdriver/remote/remote_connection.py", line 443, in _request
    resp = self._conn.request(method, url, body=body, headers=headers)
  File "/Library/Frameworks/Python.framework/Versions/3.9/lib/python3.9/site-packages/urllib3/request.py", line 78, in request
    return self.request_encode_body(
  File "/Library/Frameworks/Python.framework/Versions/3.9/lib/python3.9/site-packages/urllib3/request.py", line 170, in request_encode_body
    return self.urlopen(method, url, **extra_kw)
  File "/Library/Frameworks/Python.framework/Versions/3.9/lib/python3.9/site-packages/urllib3/poolmanager.py", line 375, in urlopen
    response = conn.urlopen(method, u.request_uri, **kw)
  File "/Library/Frameworks/Python.framework/Versions/3.9/lib/python3.9/site-packages/urllib3/connectionpool.py", line 783, in urlopen
    return self.urlopen(
  File "/Library/Frameworks/Python.framework/Versions/3.9/lib/python3.9/site-packages/urllib3/connectionpool.py", line 783, in urlopen
    return self.urlopen(
  File "/Library/Frameworks/Python.framework/Versions/3.9/lib/python3.9/site-packages/urllib3/connectionpool.py", line 783, in urlopen
    return self.urlopen(
  File "/Library/Frameworks/Python.framework/Versions/3.9/lib/python3.9/site-packages/urllib3/connectionpool.py", line 755, in urlopen
    retries = retries.increment(
  File "/Library/Frameworks/Python.framework/Versions/3.9/lib/python3.9/site-packages/urllib3/util/retry.py", line 574, in increment
    raise MaxRetryError(_pool, url, error or ResponseError(cause))
urllib3.exceptions.MaxRetryError: HTTPConnectionPool(host='localhost', port=63523): Max retries exceeded with url: /session/c57442b967fbcf49e513a96fb69780d5/url (Caused by NewConnectionError('<urllib3.connection.HTTPConnection object at 0x102e36040>: Failed to establish a new connection: [Errno 61] Connection refused'))

Traceback (most recent call last):
  File "/Library/Frameworks/Python.framework/Versions/3.9/lib/python3.9/site-packages/urllib3/connection.py", line 174, in _new_conn
    conn = connection.create_connection(
  File "/Library/Frameworks/Python.framework/Versions/3.9/lib/python3.9/site-packages/urllib3/util/connection.py", line 96, in create_connection
    raise err
  File "/Library/Frameworks/Python.framework/Versions/3.9/lib/python3.9/site-packages/urllib3/util/connection.py", line 86, in create_connection
    sock.connect(sa)
ConnectionRefusedError: [Errno 61] Connection refused

During handling of the above exception, another exception occurred:

Traceback (most recent call last):
  File "/Library/Frameworks/Python.framework/Versions/3.9/lib/python3.9/site-packages/urllib3/connectionpool.py", line 699, in urlopen
    httplib_response = self._make_request(
  File "/Library/Frameworks/Python.framework/Versions/3.9/lib/python3.9/site-packages/urllib3/connectionpool.py", line 394, in _make_request
    conn.request(method, url, **httplib_request_kw)
  File "/Library/Frameworks/Python.framework/Versions/3.9/lib/python3.9/site-packages/urllib3/connection.py", line 239, in request
    super(HTTPConnection, self).request(method, url, body=body, headers=headers)
  File "/Library/Frameworks/Python.framework/Versions/3.9/lib/python3.9/http/client.py", line 1285, in request
    self._send_request(method, url, body, headers, encode_chunked)
  File "/Library/Frameworks/Python.framework/Versions/3.9/lib/python3.9/http/client.py", line 1331, in _send_request
    self.endheaders(body, encode_chunked=encode_chunked)
  File "/Library/Frameworks/Python.framework/Versions/3.9/lib/python3.9/http/client.py", line 1280, in endheaders
    self._send_output(message_body, encode_chunked=encode_chunked)
  File "/Library/Frameworks/Python.framework/Versions/3.9/lib/python3.9/http/client.py", line 1040, in _send_output
    self.send(msg)
  File "/Library/Frameworks/Python.framework/Versions/3.9/lib/python3.9/http/client.py", line 980, in send
    self.connect()
  File "/Library/Frameworks/Python.framework/Versions/3.9/lib/python3.9/site-packages/urllib3/connection.py", line 205, in connect
    conn = self._new_conn()
  File "/Library/Frameworks/Python.framework/Versions/3.9/lib/python3.9/site-packages/urllib3/connection.py", line 186, in _new_conn
    raise NewConnectionError(
urllib3.exceptions.NewConnectionError: <urllib3.connection.HTTPConnection object at 0x102e34e80>: Failed to establish a new connection: [Errno 61] Connection refused

During handling of the above exception, another exception occurred:

Traceback (most recent call last):
  File "/Users/nathanrush/feast-monorepo/backend/Cart.py", line 186, in _add_ingredient
    added_ingredient = self._add_ingredient_on_page(ingredient_link.link, ingredient)
  File "/Users/nathanrush/feast-monorepo/backend/Cart.py", line 259, in _add_ingredient_on_page
    self.driver.get(link)
  File "/Library/Frameworks/Python.framework/Versions/3.9/lib/python3.9/site-packages/selenium/webdriver/remote/webdriver.py", line 436, in get
    self.execute(Command.GET, {'url': url})
  File "/Library/Frameworks/Python.framework/Versions/3.9/lib/python3.9/site-packages/selenium/webdriver/remote/webdriver.py", line 422, in execute
    response = self.command_executor.execute(driver_command, params)
  File "/Library/Frameworks/Python.framework/Versions/3.9/lib/python3.9/site-packages/selenium/webdriver/remote/remote_connection.py", line 421, in execute
    return self._request(command_info[0], url, body=data)
  File "/Library/Frameworks/Python.framework/Versions/3.9/lib/python3.9/site-packages/selenium/webdriver/remote/remote_connection.py", line 443, in _request
    resp = self._conn.request(method, url, body=body, headers=headers)
  File "/Library/Frameworks/Python.framework/Versions/3.9/lib/python3.9/site-packages/urllib3/request.py", line 78, in request
    return self.request_encode_body(
  File "/Library/Frameworks/Python.framework/Versions/3.9/lib/python3.9/site-packages/urllib3/request.py", line 170, in request_encode_body
    return self.urlopen(method, url, **extra_kw)
  File "/Library/Frameworks/Python.framework/Versions/3.9/lib/python3.9/site-packages/urllib3/poolmanager.py", line 375, in urlopen
    response = conn.urlopen(method, u.request_uri, **kw)
  File "/Library/Frameworks/Python.framework/Versions/3.9/lib/python3.9/site-packages/urllib3/connectionpool.py", line 783, in urlopen
    return self.urlopen(
  File "/Library/Frameworks/Python.framework/Versions/3.9/lib/python3.9/site-packages/urllib3/connectionpool.py", line 783, in urlopen
    return self.urlopen(
  File "/Library/Frameworks/Python.framework/Versions/3.9/lib/python3.9/site-packages/urllib3/connectionpool.py", line 783, in urlopen
    return self.urlopen(
  File "/Library/Frameworks/Python.framework/Versions/3.9/lib/python3.9/site-packages/urllib3/connectionpool.py", line 755, in urlopen
    retries = retries.increment(
  File "/Library/Frameworks/Python.framework/Versions/3.9/lib/python3.9/site-packages/urllib3/util/retry.py", line 574, in increment
    raise MaxRetryError(_pool, url, error or ResponseError(cause))
urllib3.exceptions.MaxRetryError: HTTPConnectionPool(host='localhost', port=63523): Max retries exceeded with url: /session/c57442b967fbcf49e513a96fb69780d5/url (Caused by NewConnectionError('<urllib3.connection.HTTPConnection object at 0x102e34e80>: Failed to establish a new connection: [Errno 61] Connection refused'))

Traceback (most recent call last):
  File "/Library/Frameworks/Python.framework/Versions/3.9/lib/python3.9/site-packages/urllib3/connection.py", line 174, in _new_conn
    conn = connection.create_connection(
  File "/Library/Frameworks/Python.framework/Versions/3.9/lib/python3.9/site-packages/urllib3/util/connection.py", line 96, in create_connection
    raise err
  File "/Library/Frameworks/Python.framework/Versions/3.9/lib/python3.9/site-packages/urllib3/util/connection.py", line 86, in create_connection
    sock.connect(sa)
ConnectionRefusedError: [Errno 61] Connection refused

During handling of the above exception, another exception occurred:

Traceback (most recent call last):
  File "/Library/Frameworks/Python.framework/Versions/3.9/lib/python3.9/site-packages/urllib3/connectionpool.py", line 699, in urlopen
    httplib_response = self._make_request(
  File "/Library/Frameworks/Python.framework/Versions/3.9/lib/python3.9/site-packages/urllib3/connectionpool.py", line 394, in _make_request
    conn.request(method, url, **httplib_request_kw)
  File "/Library/Frameworks/Python.framework/Versions/3.9/lib/python3.9/site-packages/urllib3/connection.py", line 239, in request
    super(HTTPConnection, self).request(method, url, body=body, headers=headers)
  File "/Library/Frameworks/Python.framework/Versions/3.9/lib/python3.9/http/client.py", line 1285, in request
    self._send_request(method, url, body, headers, encode_chunked)
  File "/Library/Frameworks/Python.framework/Versions/3.9/lib/python3.9/http/client.py", line 1331, in _send_request
    self.endheaders(body, encode_chunked=encode_chunked)
  File "/Library/Frameworks/Python.framework/Versions/3.9/lib/python3.9/http/client.py", line 1280, in endheaders
    self._send_output(message_body, encode_chunked=encode_chunked)
  File "/Library/Frameworks/Python.framework/Versions/3.9/lib/python3.9/http/client.py", line 1040, in _send_output
    self.send(msg)
  File "/Library/Frameworks/Python.framework/Versions/3.9/lib/python3.9/http/client.py", line 980, in send
    self.connect()
  File "/Library/Frameworks/Python.framework/Versions/3.9/lib/python3.9/site-packages/urllib3/connection.py", line 205, in connect
    conn = self._new_conn()
  File "/Library/Frameworks/Python.framework/Versions/3.9/lib/python3.9/site-packages/urllib3/connection.py", line 186, in _new_conn
    raise NewConnectionError(
urllib3.exceptions.NewConnectionError: <urllib3.connection.HTTPConnection object at 0x102e332e0>: Failed to establish a new connection: [Errno 61] Connection refused

During handling of the above exception, another exception occurred:

Traceback (most recent call last):
  File "/Users/nathanrush/feast-monorepo/backend/Cart.py", line 186, in _add_ingredient
    added_ingredient = self._add_ingredient_on_page(ingredient_link.link, ingredient)
  File "/Users/nathanrush/feast-monorepo/backend/Cart.py", line 259, in _add_ingredient_on_page
    self.driver.get(link)
  File "/Library/Frameworks/Python.framework/Versions/3.9/lib/python3.9/site-packages/selenium/webdriver/remote/webdriver.py", line 436, in get
    self.execute(Command.GET, {'url': url})
  File "/Library/Frameworks/Python.framework/Versions/3.9/lib/python3.9/site-packages/selenium/webdriver/remote/webdriver.py", line 422, in execute
    response = self.command_executor.execute(driver_command, params)
  File "/Library/Frameworks/Python.framework/Versions/3.9/lib/python3.9/site-packages/selenium/webdriver/remote/remote_connection.py", line 421, in execute
    return self._request(command_info[0], url, body=data)
  File "/Library/Frameworks/Python.framework/Versions/3.9/lib/python3.9/site-packages/selenium/webdriver/remote/remote_connection.py", line 443, in _request
    resp = self._conn.request(method, url, body=body, headers=headers)
  File "/Library/Frameworks/Python.framework/Versions/3.9/lib/python3.9/site-packages/urllib3/request.py", line 78, in request
    return self.request_encode_body(
  File "/Library/Frameworks/Python.framework/Versions/3.9/lib/python3.9/site-packages/urllib3/request.py", line 170, in request_encode_body
    return self.urlopen(method, url, **extra_kw)
  File "/Library/Frameworks/Python.framework/Versions/3.9/lib/python3.9/site-packages/urllib3/poolmanager.py", line 375, in urlopen
    response = conn.urlopen(method, u.request_uri, **kw)
  File "/Library/Frameworks/Python.framework/Versions/3.9/lib/python3.9/site-packages/urllib3/connectionpool.py", line 783, in urlopen
    return self.urlopen(
  File "/Library/Frameworks/Python.framework/Versions/3.9/lib/python3.9/site-packages/urllib3/connectionpool.py", line 783, in urlopen
    return self.urlopen(
  File "/Library/Frameworks/Python.framework/Versions/3.9/lib/python3.9/site-packages/urllib3/connectionpool.py", line 783, in urlopen
    return self.urlopen(
  File "/Library/Frameworks/Python.framework/Versions/3.9/lib/python3.9/site-packages/urllib3/connectionpool.py", line 755, in urlopen
    retries = retries.increment(
  File "/Library/Frameworks/Python.framework/Versions/3.9/lib/python3.9/site-packages/urllib3/util/retry.py", line 574, in increment
    raise MaxRetryError(_pool, url, error or ResponseError(cause))
urllib3.exceptions.MaxRetryError: HTTPConnectionPool(host='localhost', port=63523): Max retries exceeded with url: /session/c57442b967fbcf49e513a96fb69780d5/url (Caused by NewConnectionError('<urllib3.connection.HTTPConnection object at 0x102e332e0>: Failed to establish a new connection: [Errno 61] Connection refused'))

Traceback (most recent call last):
  File "/Library/Frameworks/Python.framework/Versions/3.9/lib/python3.9/site-packages/urllib3/connection.py", line 174, in _new_conn
    conn = connection.create_connection(
  File "/Library/Frameworks/Python.framework/Versions/3.9/lib/python3.9/site-packages/urllib3/util/connection.py", line 96, in create_connection
    raise err
  File "/Library/Frameworks/Python.framework/Versions/3.9/lib/python3.9/site-packages/urllib3/util/connection.py", line 86, in create_connection
    sock.connect(sa)
ConnectionRefusedError: [Errno 61] Connection refused

During handling of the above exception, another exception occurred:

Traceback (most recent call last):
  File "/Library/Frameworks/Python.framework/Versions/3.9/lib/python3.9/site-packages/urllib3/connectionpool.py", line 699, in urlopen
    httplib_response = self._make_request(
  File "/Library/Frameworks/Python.framework/Versions/3.9/lib/python3.9/site-packages/urllib3/connectionpool.py", line 394, in _make_request
    conn.request(method, url, **httplib_request_kw)
  File "/Library/Frameworks/Python.framework/Versions/3.9/lib/python3.9/site-packages/urllib3/connection.py", line 239, in request
    super(HTTPConnection, self).request(method, url, body=body, headers=headers)
  File "/Library/Frameworks/Python.framework/Versions/3.9/lib/python3.9/http/client.py", line 1285, in request
    self._send_request(method, url, body, headers, encode_chunked)
  File "/Library/Frameworks/Python.framework/Versions/3.9/lib/python3.9/http/client.py", line 1331, in _send_request
    self.endheaders(body, encode_chunked=encode_chunked)
  File "/Library/Frameworks/Python.framework/Versions/3.9/lib/python3.9/http/client.py", line 1280, in endheaders
    self._send_output(message_body, encode_chunked=encode_chunked)
  File "/Library/Frameworks/Python.framework/Versions/3.9/lib/python3.9/http/client.py", line 1040, in _send_output
    self.send(msg)
  File "/Library/Frameworks/Python.framework/Versions/3.9/lib/python3.9/http/client.py", line 980, in send
    self.connect()
  File "/Library/Frameworks/Python.framework/Versions/3.9/lib/python3.9/site-packages/urllib3/connection.py", line 205, in connect
    conn = self._new_conn()
  File "/Library/Frameworks/Python.framework/Versions/3.9/lib/python3.9/site-packages/urllib3/connection.py", line 186, in _new_conn
    raise NewConnectionError(
urllib3.exceptions.NewConnectionError: <urllib3.connection.HTTPConnection object at 0x102e364f0>: Failed to establish a new connection: [Errno 61] Connection refused

During handling of the above exception, another exception occurred:

Traceback (most recent call last):
  File "/Users/nathanrush/feast-monorepo/backend/Cart.py", line 186, in _add_ingredient
    added_ingredient = self._add_ingredient_on_page(ingredient_link.link, ingredient)
  File "/Users/nathanrush/feast-monorepo/backend/Cart.py", line 259, in _add_ingredient_on_page
    self.driver.get(link)
  File "/Library/Frameworks/Python.framework/Versions/3.9/lib/python3.9/site-packages/selenium/webdriver/remote/webdriver.py", line 436, in get
    self.execute(Command.GET, {'url': url})
  File "/Library/Frameworks/Python.framework/Versions/3.9/lib/python3.9/site-packages/selenium/webdriver/remote/webdriver.py", line 422, in execute
    response = self.command_executor.execute(driver_command, params)
  File "/Library/Frameworks/Python.framework/Versions/3.9/lib/python3.9/site-packages/selenium/webdriver/remote/remote_connection.py", line 421, in execute
    return self._request(command_info[0], url, body=data)
  File "/Library/Frameworks/Python.framework/Versions/3.9/lib/python3.9/site-packages/selenium/webdriver/remote/remote_connection.py", line 443, in _request
    resp = self._conn.request(method, url, body=body, headers=headers)
  File "/Library/Frameworks/Python.framework/Versions/3.9/lib/python3.9/site-packages/urllib3/request.py", line 78, in request
    return self.request_encode_body(
  File "/Library/Frameworks/Python.framework/Versions/3.9/lib/python3.9/site-packages/urllib3/request.py", line 170, in request_encode_body
    return self.urlopen(method, url, **extra_kw)
  File "/Library/Frameworks/Python.framework/Versions/3.9/lib/python3.9/site-packages/urllib3/poolmanager.py", line 375, in urlopen
    response = conn.urlopen(method, u.request_uri, **kw)
  File "/Library/Frameworks/Python.framework/Versions/3.9/lib/python3.9/site-packages/urllib3/connectionpool.py", line 783, in urlopen
    return self.urlopen(
  File "/Library/Frameworks/Python.framework/Versions/3.9/lib/python3.9/site-packages/urllib3/connectionpool.py", line 783, in urlopen
    return self.urlopen(
  File "/Library/Frameworks/Python.framework/Versions/3.9/lib/python3.9/site-packages/urllib3/connectionpool.py", line 783, in urlopen
    return self.urlopen(
  File "/Library/Frameworks/Python.framework/Versions/3.9/lib/python3.9/site-packages/urllib3/connectionpool.py", line 755, in urlopen
    retries = retries.increment(
  File "/Library/Frameworks/Python.framework/Versions/3.9/lib/python3.9/site-packages/urllib3/util/retry.py", line 574, in increment
    raise MaxRetryError(_pool, url, error or ResponseError(cause))
urllib3.exceptions.MaxRetryError: HTTPConnectionPool(host='localhost', port=63523): Max retries exceeded with url: /session/c57442b967fbcf49e513a96fb69780d5/url (Caused by NewConnectionError('<urllib3.connection.HTTPConnection object at 0x102e364f0>: Failed to establish a new connection: [Errno 61] Connection refused'))

Traceback (most recent call last):
  File "/Library/Frameworks/Python.framework/Versions/3.9/lib/python3.9/site-packages/urllib3/connection.py", line 174, in _new_conn
    conn = connection.create_connection(
  File "/Library/Frameworks/Python.framework/Versions/3.9/lib/python3.9/site-packages/urllib3/util/connection.py", line 96, in create_connection
    raise err
  File "/Library/Frameworks/Python.framework/Versions/3.9/lib/python3.9/site-packages/urllib3/util/connection.py", line 86, in create_connection
    sock.connect(sa)
ConnectionRefusedError: [Errno 61] Connection refused

During handling of the above exception, another exception occurred:

Traceback (most recent call last):
  File "/Library/Frameworks/Python.framework/Versions/3.9/lib/python3.9/site-packages/urllib3/connectionpool.py", line 699, in urlopen
    httplib_response = self._make_request(
  File "/Library/Frameworks/Python.framework/Versions/3.9/lib/python3.9/site-packages/urllib3/connectionpool.py", line 394, in _make_request
    conn.request(method, url, **httplib_request_kw)
  File "/Library/Frameworks/Python.framework/Versions/3.9/lib/python3.9/site-packages/urllib3/connection.py", line 239, in request
    super(HTTPConnection, self).request(method, url, body=body, headers=headers)
  File "/Library/Frameworks/Python.framework/Versions/3.9/lib/python3.9/http/client.py", line 1285, in request
    self._send_request(method, url, body, headers, encode_chunked)
  File "/Library/Frameworks/Python.framework/Versions/3.9/lib/python3.9/http/client.py", line 1331, in _send_request
    self.endheaders(body, encode_chunked=encode_chunked)
  File "/Library/Frameworks/Python.framework/Versions/3.9/lib/python3.9/http/client.py", line 1280, in endheaders
    self._send_output(message_body, encode_chunked=encode_chunked)
  File "/Library/Frameworks/Python.framework/Versions/3.9/lib/python3.9/http/client.py", line 1040, in _send_output
    self.send(msg)
  File "/Library/Frameworks/Python.framework/Versions/3.9/lib/python3.9/http/client.py", line 980, in send
    self.connect()
  File "/Library/Frameworks/Python.framework/Versions/3.9/lib/python3.9/site-packages/urllib3/connection.py", line 205, in connect
    conn = self._new_conn()
  File "/Library/Frameworks/Python.framework/Versions/3.9/lib/python3.9/site-packages/urllib3/connection.py", line 186, in _new_conn
    raise NewConnectionError(
urllib3.exceptions.NewConnectionError: <urllib3.connection.HTTPConnection object at 0x102e39850>: Failed to establish a new connection: [Errno 61] Connection refused

During handling of the above exception, another exception occurred:

Traceback (most recent call last):
  File "/Users/nathanrush/feast-monorepo/backend/Cart.py", line 186, in _add_ingredient
    added_ingredient = self._add_ingredient_on_page(ingredient_link.link, ingredient)
  File "/Users/nathanrush/feast-monorepo/backend/Cart.py", line 259, in _add_ingredient_on_page
    self.driver.get(link)
  File "/Library/Frameworks/Python.framework/Versions/3.9/lib/python3.9/site-packages/selenium/webdriver/remote/webdriver.py", line 436, in get
    self.execute(Command.GET, {'url': url})
  File "/Library/Frameworks/Python.framework/Versions/3.9/lib/python3.9/site-packages/selenium/webdriver/remote/webdriver.py", line 422, in execute
    response = self.command_executor.execute(driver_command, params)
  File "/Library/Frameworks/Python.framework/Versions/3.9/lib/python3.9/site-packages/selenium/webdriver/remote/remote_connection.py", line 421, in execute
    return self._request(command_info[0], url, body=data)
  File "/Library/Frameworks/Python.framework/Versions/3.9/lib/python3.9/site-packages/selenium/webdriver/remote/remote_connection.py", line 443, in _request
    resp = self._conn.request(method, url, body=body, headers=headers)
  File "/Library/Frameworks/Python.framework/Versions/3.9/lib/python3.9/site-packages/urllib3/request.py", line 78, in request
    return self.request_encode_body(
  File "/Library/Frameworks/Python.framework/Versions/3.9/lib/python3.9/site-packages/urllib3/request.py", line 170, in request_encode_body
    return self.urlopen(method, url, **extra_kw)
  File "/Library/Frameworks/Python.framework/Versions/3.9/lib/python3.9/site-packages/urllib3/poolmanager.py", line 375, in urlopen
    response = conn.urlopen(method, u.request_uri, **kw)
  File "/Library/Frameworks/Python.framework/Versions/3.9/lib/python3.9/site-packages/urllib3/connectionpool.py", line 783, in urlopen
    return self.urlopen(
  File "/Library/Frameworks/Python.framework/Versions/3.9/lib/python3.9/site-packages/urllib3/connectionpool.py", line 783, in urlopen
    return self.urlopen(
  File "/Library/Frameworks/Python.framework/Versions/3.9/lib/python3.9/site-packages/urllib3/connectionpool.py", line 783, in urlopen
    return self.urlopen(
  File "/Library/Frameworks/Python.framework/Versions/3.9/lib/python3.9/site-packages/urllib3/connectionpool.py", line 755, in urlopen
    retries = retries.increment(
  File "/Library/Frameworks/Python.framework/Versions/3.9/lib/python3.9/site-packages/urllib3/util/retry.py", line 574, in increment
    raise MaxRetryError(_pool, url, error or ResponseError(cause))
urllib3.exceptions.MaxRetryError: HTTPConnectionPool(host='localhost', port=63523): Max retries exceeded with url: /session/c57442b967fbcf49e513a96fb69780d5/url (Caused by NewConnectionError('<urllib3.connection.HTTPConnection object at 0x102e39850>: Failed to establish a new connection: [Errno 61] Connection refused'))

Traceback (most recent call last):
  File "/Library/Frameworks/Python.framework/Versions/3.9/lib/python3.9/site-packages/urllib3/connection.py", line 174, in _new_conn
    conn = connection.create_connection(
  File "/Library/Frameworks/Python.framework/Versions/3.9/lib/python3.9/site-packages/urllib3/util/connection.py", line 96, in create_connection
    raise err
  File "/Library/Frameworks/Python.framework/Versions/3.9/lib/python3.9/site-packages/urllib3/util/connection.py", line 86, in create_connection
    sock.connect(sa)
ConnectionRefusedError: [Errno 61] Connection refused

During handling of the above exception, another exception occurred:

Traceback (most recent call last):
  File "/Library/Frameworks/Python.framework/Versions/3.9/lib/python3.9/site-packages/urllib3/connectionpool.py", line 699, in urlopen
    httplib_response = self._make_request(
  File "/Library/Frameworks/Python.framework/Versions/3.9/lib/python3.9/site-packages/urllib3/connectionpool.py", line 394, in _make_request
    conn.request(method, url, **httplib_request_kw)
  File "/Library/Frameworks/Python.framework/Versions/3.9/lib/python3.9/site-packages/urllib3/connection.py", line 239, in request
    super(HTTPConnection, self).request(method, url, body=body, headers=headers)
  File "/Library/Frameworks/Python.framework/Versions/3.9/lib/python3.9/http/client.py", line 1285, in request
    self._send_request(method, url, body, headers, encode_chunked)
  File "/Library/Frameworks/Python.framework/Versions/3.9/lib/python3.9/http/client.py", line 1331, in _send_request
    self.endheaders(body, encode_chunked=encode_chunked)
  File "/Library/Frameworks/Python.framework/Versions/3.9/lib/python3.9/http/client.py", line 1280, in endheaders
    self._send_output(message_body, encode_chunked=encode_chunked)
  File "/Library/Frameworks/Python.framework/Versions/3.9/lib/python3.9/http/client.py", line 1040, in _send_output
    self.send(msg)
  File "/Library/Frameworks/Python.framework/Versions/3.9/lib/python3.9/http/client.py", line 980, in send
    self.connect()
  File "/Library/Frameworks/Python.framework/Versions/3.9/lib/python3.9/site-packages/urllib3/connection.py", line 205, in connect
    conn = self._new_conn()
  File "/Library/Frameworks/Python.framework/Versions/3.9/lib/python3.9/site-packages/urllib3/connection.py", line 186, in _new_conn
    raise NewConnectionError(
urllib3.exceptions.NewConnectionError: <urllib3.connection.HTTPConnection object at 0x102e39d60>: Failed to establish a new connection: [Errno 61] Connection refused

During handling of the above exception, another exception occurred:

Traceback (most recent call last):
  File "/Users/nathanrush/feast-monorepo/backend/Cart.py", line 186, in _add_ingredient
    added_ingredient = self._add_ingredient_on_page(ingredient_link.link, ingredient)
  File "/Users/nathanrush/feast-monorepo/backend/Cart.py", line 259, in _add_ingredient_on_page
    self.driver.get(link)
  File "/Library/Frameworks/Python.framework/Versions/3.9/lib/python3.9/site-packages/selenium/webdriver/remote/webdriver.py", line 436, in get
    self.execute(Command.GET, {'url': url})
  File "/Library/Frameworks/Python.framework/Versions/3.9/lib/python3.9/site-packages/selenium/webdriver/remote/webdriver.py", line 422, in execute
    response = self.command_executor.execute(driver_command, params)
  File "/Library/Frameworks/Python.framework/Versions/3.9/lib/python3.9/site-packages/selenium/webdriver/remote/remote_connection.py", line 421, in execute
    return self._request(command_info[0], url, body=data)
  File "/Library/Frameworks/Python.framework/Versions/3.9/lib/python3.9/site-packages/selenium/webdriver/remote/remote_connection.py", line 443, in _request
    resp = self._conn.request(method, url, body=body, headers=headers)
  File "/Library/Frameworks/Python.framework/Versions/3.9/lib/python3.9/site-packages/urllib3/request.py", line 78, in request
    return self.request_encode_body(
  File "/Library/Frameworks/Python.framework/Versions/3.9/lib/python3.9/site-packages/urllib3/request.py", line 170, in request_encode_body
    return self.urlopen(method, url, **extra_kw)
  File "/Library/Frameworks/Python.framework/Versions/3.9/lib/python3.9/site-packages/urllib3/poolmanager.py", line 375, in urlopen
    response = conn.urlopen(method, u.request_uri, **kw)
  File "/Library/Frameworks/Python.framework/Versions/3.9/lib/python3.9/site-packages/urllib3/connectionpool.py", line 783, in urlopen
    return self.urlopen(
  File "/Library/Frameworks/Python.framework/Versions/3.9/lib/python3.9/site-packages/urllib3/connectionpool.py", line 783, in urlopen
    return self.urlopen(
  File "/Library/Frameworks/Python.framework/Versions/3.9/lib/python3.9/site-packages/urllib3/connectionpool.py", line 783, in urlopen
    return self.urlopen(
  File "/Library/Frameworks/Python.framework/Versions/3.9/lib/python3.9/site-packages/urllib3/connectionpool.py", line 755, in urlopen
    retries = retries.increment(
  File "/Library/Frameworks/Python.framework/Versions/3.9/lib/python3.9/site-packages/urllib3/util/retry.py", line 574, in increment
    raise MaxRetryError(_pool, url, error or ResponseError(cause))
urllib3.exceptions.MaxRetryError: HTTPConnectionPool(host='localhost', port=63523): Max retries exceeded with url: /session/c57442b967fbcf49e513a96fb69780d5/url (Caused by NewConnectionError('<urllib3.connection.HTTPConnection object at 0x102e39d60>: Failed to establish a new connection: [Errno 61] Connection refused'))

Traceback (most recent call last):
  File "/Library/Frameworks/Python.framework/Versions/3.9/lib/python3.9/site-packages/urllib3/connection.py", line 174, in _new_conn
    conn = connection.create_connection(
  File "/Library/Frameworks/Python.framework/Versions/3.9/lib/python3.9/site-packages/urllib3/util/connection.py", line 96, in create_connection
    raise err
  File "/Library/Frameworks/Python.framework/Versions/3.9/lib/python3.9/site-packages/urllib3/util/connection.py", line 86, in create_connection
    sock.connect(sa)
ConnectionRefusedError: [Errno 61] Connection refused

During handling of the above exception, another exception occurred:

Traceback (most recent call last):
  File "/Library/Frameworks/Python.framework/Versions/3.9/lib/python3.9/site-packages/urllib3/connectionpool.py", line 699, in urlopen
    httplib_response = self._make_request(
  File "/Library/Frameworks/Python.framework/Versions/3.9/lib/python3.9/site-packages/urllib3/connectionpool.py", line 394, in _make_request
    conn.request(method, url, **httplib_request_kw)
  File "/Library/Frameworks/Python.framework/Versions/3.9/lib/python3.9/site-packages/urllib3/connection.py", line 239, in request
    super(HTTPConnection, self).request(method, url, body=body, headers=headers)
  File "/Library/Frameworks/Python.framework/Versions/3.9/lib/python3.9/http/client.py", line 1285, in request
    self._send_request(method, url, body, headers, encode_chunked)
  File "/Library/Frameworks/Python.framework/Versions/3.9/lib/python3.9/http/client.py", line 1331, in _send_request
    self.endheaders(body, encode_chunked=encode_chunked)
  File "/Library/Frameworks/Python.framework/Versions/3.9/lib/python3.9/http/client.py", line 1280, in endheaders
    self._send_output(message_body, encode_chunked=encode_chunked)
  File "/Library/Frameworks/Python.framework/Versions/3.9/lib/python3.9/http/client.py", line 1040, in _send_output
    self.send(msg)
  File "/Library/Frameworks/Python.framework/Versions/3.9/lib/python3.9/http/client.py", line 980, in send
    self.connect()
  File "/Library/Frameworks/Python.framework/Versions/3.9/lib/python3.9/site-packages/urllib3/connection.py", line 205, in connect
    conn = self._new_conn()
  File "/Library/Frameworks/Python.framework/Versions/3.9/lib/python3.9/site-packages/urllib3/connection.py", line 186, in _new_conn
    raise NewConnectionError(
urllib3.exceptions.NewConnectionError: <urllib3.connection.HTTPConnection object at 0x102e32370>: Failed to establish a new connection: [Errno 61] Connection refused

During handling of the above exception, another exception occurred:

Traceback (most recent call last):
  File "/Users/nathanrush/feast-monorepo/backend/Cart.py", line 186, in _add_ingredient
    added_ingredient = self._add_ingredient_on_page(ingredient_link.link, ingredient)
  File "/Users/nathanrush/feast-monorepo/backend/Cart.py", line 259, in _add_ingredient_on_page
    self.driver.get(link)
  File "/Library/Frameworks/Python.framework/Versions/3.9/lib/python3.9/site-packages/selenium/webdriver/remote/webdriver.py", line 436, in get
    self.execute(Command.GET, {'url': url})
  File "/Library/Frameworks/Python.framework/Versions/3.9/lib/python3.9/site-packages/selenium/webdriver/remote/webdriver.py", line 422, in execute
    response = self.command_executor.execute(driver_command, params)
  File "/Library/Frameworks/Python.framework/Versions/3.9/lib/python3.9/site-packages/selenium/webdriver/remote/remote_connection.py", line 421, in execute
    return self._request(command_info[0], url, body=data)
  File "/Library/Frameworks/Python.framework/Versions/3.9/lib/python3.9/site-packages/selenium/webdriver/remote/remote_connection.py", line 443, in _request
    resp = self._conn.request(method, url, body=body, headers=headers)
  File "/Library/Frameworks/Python.framework/Versions/3.9/lib/python3.9/site-packages/urllib3/request.py", line 78, in request
    return self.request_encode_body(
  File "/Library/Frameworks/Python.framework/Versions/3.9/lib/python3.9/site-packages/urllib3/request.py", line 170, in request_encode_body
    return self.urlopen(method, url, **extra_kw)
  File "/Library/Frameworks/Python.framework/Versions/3.9/lib/python3.9/site-packages/urllib3/poolmanager.py", line 375, in urlopen
    response = conn.urlopen(method, u.request_uri, **kw)
  File "/Library/Frameworks/Python.framework/Versions/3.9/lib/python3.9/site-packages/urllib3/connectionpool.py", line 783, in urlopen
    return self.urlopen(
  File "/Library/Frameworks/Python.framework/Versions/3.9/lib/python3.9/site-packages/urllib3/connectionpool.py", line 783, in urlopen
    return self.urlopen(
  File "/Library/Frameworks/Python.framework/Versions/3.9/lib/python3.9/site-packages/urllib3/connectionpool.py", line 783, in urlopen
    return self.urlopen(
  File "/Library/Frameworks/Python.framework/Versions/3.9/lib/python3.9/site-packages/urllib3/connectionpool.py", line 755, in urlopen
    retries = retries.increment(
  File "/Library/Frameworks/Python.framework/Versions/3.9/lib/python3.9/site-packages/urllib3/util/retry.py", line 574, in increment
    raise MaxRetryError(_pool, url, error or ResponseError(cause))
urllib3.exceptions.MaxRetryError: HTTPConnectionPool(host='localhost', port=63523): Max retries exceeded with url: /session/c57442b967fbcf49e513a96fb69780d5/url (Caused by NewConnectionError('<urllib3.connection.HTTPConnection object at 0x102e32370>: Failed to establish a new connection: [Errno 61] Connection refused'))

Traceback (most recent call last):
  File "/Library/Frameworks/Python.framework/Versions/3.9/lib/python3.9/site-packages/urllib3/connection.py", line 174, in _new_conn
    conn = connection.create_connection(
  File "/Library/Frameworks/Python.framework/Versions/3.9/lib/python3.9/site-packages/urllib3/util/connection.py", line 96, in create_connection
    raise err
  File "/Library/Frameworks/Python.framework/Versions/3.9/lib/python3.9/site-packages/urllib3/util/connection.py", line 86, in create_connection
    sock.connect(sa)
ConnectionRefusedError: [Errno 61] Connection refused

During handling of the above exception, another exception occurred:

Traceback (most recent call last):
  File "/Library/Frameworks/Python.framework/Versions/3.9/lib/python3.9/site-packages/urllib3/connectionpool.py", line 699, in urlopen
    httplib_response = self._make_request(
  File "/Library/Frameworks/Python.framework/Versions/3.9/lib/python3.9/site-packages/urllib3/connectionpool.py", line 394, in _make_request
    conn.request(method, url, **httplib_request_kw)
  File "/Library/Frameworks/Python.framework/Versions/3.9/lib/python3.9/site-packages/urllib3/connection.py", line 239, in request
    super(HTTPConnection, self).request(method, url, body=body, headers=headers)
  File "/Library/Frameworks/Python.framework/Versions/3.9/lib/python3.9/http/client.py", line 1285, in request
    self._send_request(method, url, body, headers, encode_chunked)
  File "/Library/Frameworks/Python.framework/Versions/3.9/lib/python3.9/http/client.py", line 1331, in _send_request
    self.endheaders(body, encode_chunked=encode_chunked)
  File "/Library/Frameworks/Python.framework/Versions/3.9/lib/python3.9/http/client.py", line 1280, in endheaders
    self._send_output(message_body, encode_chunked=encode_chunked)
  File "/Library/Frameworks/Python.framework/Versions/3.9/lib/python3.9/http/client.py", line 1040, in _send_output
    self.send(msg)
  File "/Library/Frameworks/Python.framework/Versions/3.9/lib/python3.9/http/client.py", line 980, in send
    self.connect()
  File "/Library/Frameworks/Python.framework/Versions/3.9/lib/python3.9/site-packages/urllib3/connection.py", line 205, in connect
    conn = self._new_conn()
  File "/Library/Frameworks/Python.framework/Versions/3.9/lib/python3.9/site-packages/urllib3/connection.py", line 186, in _new_conn
    raise NewConnectionError(
urllib3.exceptions.NewConnectionError: <urllib3.connection.HTTPConnection object at 0x102e34e50>: Failed to establish a new connection: [Errno 61] Connection refused

During handling of the above exception, another exception occurred:

Traceback (most recent call last):
  File "/Users/nathanrush/feast-monorepo/backend/Cart.py", line 186, in _add_ingredient
    added_ingredient = self._add_ingredient_on_page(ingredient_link.link, ingredient)
  File "/Users/nathanrush/feast-monorepo/backend/Cart.py", line 259, in _add_ingredient_on_page
    self.driver.get(link)
  File "/Library/Frameworks/Python.framework/Versions/3.9/lib/python3.9/site-packages/selenium/webdriver/remote/webdriver.py", line 436, in get
    self.execute(Command.GET, {'url': url})
  File "/Library/Frameworks/Python.framework/Versions/3.9/lib/python3.9/site-packages/selenium/webdriver/remote/webdriver.py", line 422, in execute
    response = self.command_executor.execute(driver_command, params)
  File "/Library/Frameworks/Python.framework/Versions/3.9/lib/python3.9/site-packages/selenium/webdriver/remote/remote_connection.py", line 421, in execute
    return self._request(command_info[0], url, body=data)
  File "/Library/Frameworks/Python.framework/Versions/3.9/lib/python3.9/site-packages/selenium/webdriver/remote/remote_connection.py", line 443, in _request
    resp = self._conn.request(method, url, body=body, headers=headers)
  File "/Library/Frameworks/Python.framework/Versions/3.9/lib/python3.9/site-packages/urllib3/request.py", line 78, in request
    return self.request_encode_body(
  File "/Library/Frameworks/Python.framework/Versions/3.9/lib/python3.9/site-packages/urllib3/request.py", line 170, in request_encode_body
    return self.urlopen(method, url, **extra_kw)
  File "/Library/Frameworks/Python.framework/Versions/3.9/lib/python3.9/site-packages/urllib3/poolmanager.py", line 375, in urlopen
    response = conn.urlopen(method, u.request_uri, **kw)
  File "/Library/Frameworks/Python.framework/Versions/3.9/lib/python3.9/site-packages/urllib3/connectionpool.py", line 783, in urlopen
    return self.urlopen(
  File "/Library/Frameworks/Python.framework/Versions/3.9/lib/python3.9/site-packages/urllib3/connectionpool.py", line 783, in urlopen
    return self.urlopen(
  File "/Library/Frameworks/Python.framework/Versions/3.9/lib/python3.9/site-packages/urllib3/connectionpool.py", line 783, in urlopen
    return self.urlopen(
  File "/Library/Frameworks/Python.framework/Versions/3.9/lib/python3.9/site-packages/urllib3/connectionpool.py", line 755, in urlopen
    retries = retries.increment(
  File "/Library/Frameworks/Python.framework/Versions/3.9/lib/python3.9/site-packages/urllib3/util/retry.py", line 574, in increment
    raise MaxRetryError(_pool, url, error or ResponseError(cause))
urllib3.exceptions.MaxRetryError: HTTPConnectionPool(host='localhost', port=63523): Max retries exceeded with url: /session/c57442b967fbcf49e513a96fb69780d5/url (Caused by NewConnectionError('<urllib3.connection.HTTPConnection object at 0x102e34e50>: Failed to establish a new connection: [Errno 61] Connection refused'))

Traceback (most recent call last):
  File "/Library/Frameworks/Python.framework/Versions/3.9/lib/python3.9/site-packages/urllib3/connection.py", line 174, in _new_conn
    conn = connection.create_connection(
  File "/Library/Frameworks/Python.framework/Versions/3.9/lib/python3.9/site-packages/urllib3/util/connection.py", line 96, in create_connection
    raise err
  File "/Library/Frameworks/Python.framework/Versions/3.9/lib/python3.9/site-packages/urllib3/util/connection.py", line 86, in create_connection
    sock.connect(sa)
ConnectionRefusedError: [Errno 61] Connection refused

During handling of the above exception, another exception occurred:

Traceback (most recent call last):
  File "/Library/Frameworks/Python.framework/Versions/3.9/lib/python3.9/site-packages/urllib3/connectionpool.py", line 699, in urlopen
    httplib_response = self._make_request(
  File "/Library/Frameworks/Python.framework/Versions/3.9/lib/python3.9/site-packages/urllib3/connectionpool.py", line 394, in _make_request
    conn.request(method, url, **httplib_request_kw)
  File "/Library/Frameworks/Python.framework/Versions/3.9/lib/python3.9/site-packages/urllib3/connection.py", line 239, in request
    super(HTTPConnection, self).request(method, url, body=body, headers=headers)
  File "/Library/Frameworks/Python.framework/Versions/3.9/lib/python3.9/http/client.py", line 1285, in request
    self._send_request(method, url, body, headers, encode_chunked)
  File "/Library/Frameworks/Python.framework/Versions/3.9/lib/python3.9/http/client.py", line 1331, in _send_request
    self.endheaders(body, encode_chunked=encode_chunked)
  File "/Library/Frameworks/Python.framework/Versions/3.9/lib/python3.9/http/client.py", line 1280, in endheaders
    self._send_output(message_body, encode_chunked=encode_chunked)
  File "/Library/Frameworks/Python.framework/Versions/3.9/lib/python3.9/http/client.py", line 1040, in _send_output
    self.send(msg)
  File "/Library/Frameworks/Python.framework/Versions/3.9/lib/python3.9/http/client.py", line 980, in send
    self.connect()
  File "/Library/Frameworks/Python.framework/Versions/3.9/lib/python3.9/site-packages/urllib3/connection.py", line 205, in connect
    conn = self._new_conn()
  File "/Library/Frameworks/Python.framework/Versions/3.9/lib/python3.9/site-packages/urllib3/connection.py", line 186, in _new_conn
    raise NewConnectionError(
urllib3.exceptions.NewConnectionError: <urllib3.connection.HTTPConnection object at 0x102e36040>: Failed to establish a new connection: [Errno 61] Connection refused

During handling of the above exception, another exception occurred:

Traceback (most recent call last):
  File "/Users/nathanrush/feast-monorepo/backend/Cart.py", line 186, in _add_ingredient
    added_ingredient = self._add_ingredient_on_page(ingredient_link.link, ingredient)
  File "/Users/nathanrush/feast-monorepo/backend/Cart.py", line 259, in _add_ingredient_on_page
    self.driver.get(link)
  File "/Library/Frameworks/Python.framework/Versions/3.9/lib/python3.9/site-packages/selenium/webdriver/remote/webdriver.py", line 436, in get
    self.execute(Command.GET, {'url': url})
  File "/Library/Frameworks/Python.framework/Versions/3.9/lib/python3.9/site-packages/selenium/webdriver/remote/webdriver.py", line 422, in execute
    response = self.command_executor.execute(driver_command, params)
  File "/Library/Frameworks/Python.framework/Versions/3.9/lib/python3.9/site-packages/selenium/webdriver/remote/remote_connection.py", line 421, in execute
    return self._request(command_info[0], url, body=data)
  File "/Library/Frameworks/Python.framework/Versions/3.9/lib/python3.9/site-packages/selenium/webdriver/remote/remote_connection.py", line 443, in _request
    resp = self._conn.request(method, url, body=body, headers=headers)
  File "/Library/Frameworks/Python.framework/Versions/3.9/lib/python3.9/site-packages/urllib3/request.py", line 78, in request
    return self.request_encode_body(
  File "/Library/Frameworks/Python.framework/Versions/3.9/lib/python3.9/site-packages/urllib3/request.py", line 170, in request_encode_body
    return self.urlopen(method, url, **extra_kw)
  File "/Library/Frameworks/Python.framework/Versions/3.9/lib/python3.9/site-packages/urllib3/poolmanager.py", line 375, in urlopen
    response = conn.urlopen(method, u.request_uri, **kw)
  File "/Library/Frameworks/Python.framework/Versions/3.9/lib/python3.9/site-packages/urllib3/connectionpool.py", line 783, in urlopen
    return self.urlopen(
  File "/Library/Frameworks/Python.framework/Versions/3.9/lib/python3.9/site-packages/urllib3/connectionpool.py", line 783, in urlopen
    return self.urlopen(
  File "/Library/Frameworks/Python.framework/Versions/3.9/lib/python3.9/site-packages/urllib3/connectionpool.py", line 783, in urlopen
    return self.urlopen(
  File "/Library/Frameworks/Python.framework/Versions/3.9/lib/python3.9/site-packages/urllib3/connectionpool.py", line 755, in urlopen
    retries = retries.increment(
  File "/Library/Frameworks/Python.framework/Versions/3.9/lib/python3.9/site-packages/urllib3/util/retry.py", line 574, in increment
    raise MaxRetryError(_pool, url, error or ResponseError(cause))
urllib3.exceptions.MaxRetryError: HTTPConnectionPool(host='localhost', port=63523): Max retries exceeded with url: /session/c57442b967fbcf49e513a96fb69780d5/url (Caused by NewConnectionError('<urllib3.connection.HTTPConnection object at 0x102e36040>: Failed to establish a new connection: [Errno 61] Connection refused'))

Traceback (most recent call last):
  File "/Library/Frameworks/Python.framework/Versions/3.9/lib/python3.9/site-packages/urllib3/connection.py", line 174, in _new_conn
    conn = connection.create_connection(
  File "/Library/Frameworks/Python.framework/Versions/3.9/lib/python3.9/site-packages/urllib3/util/connection.py", line 96, in create_connection
    raise err
  File "/Library/Frameworks/Python.framework/Versions/3.9/lib/python3.9/site-packages/urllib3/util/connection.py", line 86, in create_connection
    sock.connect(sa)
ConnectionRefusedError: [Errno 61] Connection refused

During handling of the above exception, another exception occurred:

Traceback (most recent call last):
  File "/Library/Frameworks/Python.framework/Versions/3.9/lib/python3.9/site-packages/urllib3/connectionpool.py", line 699, in urlopen
    httplib_response = self._make_request(
  File "/Library/Frameworks/Python.framework/Versions/3.9/lib/python3.9/site-packages/urllib3/connectionpool.py", line 394, in _make_request
    conn.request(method, url, **httplib_request_kw)
  File "/Library/Frameworks/Python.framework/Versions/3.9/lib/python3.9/site-packages/urllib3/connection.py", line 239, in request
    super(HTTPConnection, self).request(method, url, body=body, headers=headers)
  File "/Library/Frameworks/Python.framework/Versions/3.9/lib/python3.9/http/client.py", line 1285, in request
    self._send_request(method, url, body, headers, encode_chunked)
  File "/Library/Frameworks/Python.framework/Versions/3.9/lib/python3.9/http/client.py", line 1331, in _send_request
    self.endheaders(body, encode_chunked=encode_chunked)
  File "/Library/Frameworks/Python.framework/Versions/3.9/lib/python3.9/http/client.py", line 1280, in endheaders
    self._send_output(message_body, encode_chunked=encode_chunked)
  File "/Library/Frameworks/Python.framework/Versions/3.9/lib/python3.9/http/client.py", line 1040, in _send_output
    self.send(msg)
  File "/Library/Frameworks/Python.framework/Versions/3.9/lib/python3.9/http/client.py", line 980, in send
    self.connect()
  File "/Library/Frameworks/Python.framework/Versions/3.9/lib/python3.9/site-packages/urllib3/connection.py", line 205, in connect
    conn = self._new_conn()
  File "/Library/Frameworks/Python.framework/Versions/3.9/lib/python3.9/site-packages/urllib3/connection.py", line 186, in _new_conn
    raise NewConnectionError(
urllib3.exceptions.NewConnectionError: <urllib3.connection.HTTPConnection object at 0x1076ce970>: Failed to establish a new connection: [Errno 61] Connection refused

During handling of the above exception, another exception occurred:

Traceback (most recent call last):
  File "/Users/nathanrush/feast-monorepo/backend/Cart.py", line 186, in _add_ingredient
    added_ingredient = self._add_ingredient_on_page(ingredient_link.link, ingredient)
  File "/Users/nathanrush/feast-monorepo/backend/Cart.py", line 259, in _add_ingredient_on_page
    self.driver.get(link)
  File "/Library/Frameworks/Python.framework/Versions/3.9/lib/python3.9/site-packages/selenium/webdriver/remote/webdriver.py", line 436, in get
    self.execute(Command.GET, {'url': url})
  File "/Library/Frameworks/Python.framework/Versions/3.9/lib/python3.9/site-packages/selenium/webdriver/remote/webdriver.py", line 422, in execute
    response = self.command_executor.execute(driver_command, params)
  File "/Library/Frameworks/Python.framework/Versions/3.9/lib/python3.9/site-packages/selenium/webdriver/remote/remote_connection.py", line 421, in execute
    return self._request(command_info[0], url, body=data)
  File "/Library/Frameworks/Python.framework/Versions/3.9/lib/python3.9/site-packages/selenium/webdriver/remote/remote_connection.py", line 443, in _request
    resp = self._conn.request(method, url, body=body, headers=headers)
  File "/Library/Frameworks/Python.framework/Versions/3.9/lib/python3.9/site-packages/urllib3/request.py", line 78, in request
    return self.request_encode_body(
  File "/Library/Frameworks/Python.framework/Versions/3.9/lib/python3.9/site-packages/urllib3/request.py", line 170, in request_encode_body
    return self.urlopen(method, url, **extra_kw)
  File "/Library/Frameworks/Python.framework/Versions/3.9/lib/python3.9/site-packages/urllib3/poolmanager.py", line 375, in urlopen
    response = conn.urlopen(method, u.request_uri, **kw)
  File "/Library/Frameworks/Python.framework/Versions/3.9/lib/python3.9/site-packages/urllib3/connectionpool.py", line 783, in urlopen
    return self.urlopen(
  File "/Library/Frameworks/Python.framework/Versions/3.9/lib/python3.9/site-packages/urllib3/connectionpool.py", line 783, in urlopen
    return self.urlopen(
  File "/Library/Frameworks/Python.framework/Versions/3.9/lib/python3.9/site-packages/urllib3/connectionpool.py", line 783, in urlopen
    return self.urlopen(
  File "/Library/Frameworks/Python.framework/Versions/3.9/lib/python3.9/site-packages/urllib3/connectionpool.py", line 755, in urlopen
    retries = retries.increment(
  File "/Library/Frameworks/Python.framework/Versions/3.9/lib/python3.9/site-packages/urllib3/util/retry.py", line 574, in increment
    raise MaxRetryError(_pool, url, error or ResponseError(cause))
urllib3.exceptions.MaxRetryError: HTTPConnectionPool(host='localhost', port=63523): Max retries exceeded with url: /session/c57442b967fbcf49e513a96fb69780d5/url (Caused by NewConnectionError('<urllib3.connection.HTTPConnection object at 0x1076ce970>: Failed to establish a new connection: [Errno 61] Connection refused'))

Traceback (most recent call last):
  File "/Library/Frameworks/Python.framework/Versions/3.9/lib/python3.9/site-packages/urllib3/connection.py", line 174, in _new_conn
    conn = connection.create_connection(
  File "/Library/Frameworks/Python.framework/Versions/3.9/lib/python3.9/site-packages/urllib3/util/connection.py", line 96, in create_connection
    raise err
  File "/Library/Frameworks/Python.framework/Versions/3.9/lib/python3.9/site-packages/urllib3/util/connection.py", line 86, in create_connection
    sock.connect(sa)
ConnectionRefusedError: [Errno 61] Connection refused

During handling of the above exception, another exception occurred:

Traceback (most recent call last):
  File "/Library/Frameworks/Python.framework/Versions/3.9/lib/python3.9/site-packages/urllib3/connectionpool.py", line 699, in urlopen
    httplib_response = self._make_request(
  File "/Library/Frameworks/Python.framework/Versions/3.9/lib/python3.9/site-packages/urllib3/connectionpool.py", line 394, in _make_request
    conn.request(method, url, **httplib_request_kw)
  File "/Library/Frameworks/Python.framework/Versions/3.9/lib/python3.9/site-packages/urllib3/connection.py", line 239, in request
    super(HTTPConnection, self).request(method, url, body=body, headers=headers)
  File "/Library/Frameworks/Python.framework/Versions/3.9/lib/python3.9/http/client.py", line 1285, in request
    self._send_request(method, url, body, headers, encode_chunked)
  File "/Library/Frameworks/Python.framework/Versions/3.9/lib/python3.9/http/client.py", line 1331, in _send_request
    self.endheaders(body, encode_chunked=encode_chunked)
  File "/Library/Frameworks/Python.framework/Versions/3.9/lib/python3.9/http/client.py", line 1280, in endheaders
    self._send_output(message_body, encode_chunked=encode_chunked)
  File "/Library/Frameworks/Python.framework/Versions/3.9/lib/python3.9/http/client.py", line 1040, in _send_output
    self.send(msg)
  File "/Library/Frameworks/Python.framework/Versions/3.9/lib/python3.9/http/client.py", line 980, in send
    self.connect()
  File "/Library/Frameworks/Python.framework/Versions/3.9/lib/python3.9/site-packages/urllib3/connection.py", line 205, in connect
    conn = self._new_conn()
  File "/Library/Frameworks/Python.framework/Versions/3.9/lib/python3.9/site-packages/urllib3/connection.py", line 186, in _new_conn
    raise NewConnectionError(
urllib3.exceptions.NewConnectionError: <urllib3.connection.HTTPConnection object at 0x1076ce940>: Failed to establish a new connection: [Errno 61] Connection refused

During handling of the above exception, another exception occurred:

Traceback (most recent call last):
  File "/Users/nathanrush/feast-monorepo/backend/Cart.py", line 186, in _add_ingredient
    added_ingredient = self._add_ingredient_on_page(ingredient_link.link, ingredient)
  File "/Users/nathanrush/feast-monorepo/backend/Cart.py", line 259, in _add_ingredient_on_page
    self.driver.get(link)
  File "/Library/Frameworks/Python.framework/Versions/3.9/lib/python3.9/site-packages/selenium/webdriver/remote/webdriver.py", line 436, in get
    self.execute(Command.GET, {'url': url})
  File "/Library/Frameworks/Python.framework/Versions/3.9/lib/python3.9/site-packages/selenium/webdriver/remote/webdriver.py", line 422, in execute
    response = self.command_executor.execute(driver_command, params)
  File "/Library/Frameworks/Python.framework/Versions/3.9/lib/python3.9/site-packages/selenium/webdriver/remote/remote_connection.py", line 421, in execute
    return self._request(command_info[0], url, body=data)
  File "/Library/Frameworks/Python.framework/Versions/3.9/lib/python3.9/site-packages/selenium/webdriver/remote/remote_connection.py", line 443, in _request
    resp = self._conn.request(method, url, body=body, headers=headers)
  File "/Library/Frameworks/Python.framework/Versions/3.9/lib/python3.9/site-packages/urllib3/request.py", line 78, in request
    return self.request_encode_body(
  File "/Library/Frameworks/Python.framework/Versions/3.9/lib/python3.9/site-packages/urllib3/request.py", line 170, in request_encode_body
    return self.urlopen(method, url, **extra_kw)
  File "/Library/Frameworks/Python.framework/Versions/3.9/lib/python3.9/site-packages/urllib3/poolmanager.py", line 375, in urlopen
    response = conn.urlopen(method, u.request_uri, **kw)
  File "/Library/Frameworks/Python.framework/Versions/3.9/lib/python3.9/site-packages/urllib3/connectionpool.py", line 783, in urlopen
    return self.urlopen(
  File "/Library/Frameworks/Python.framework/Versions/3.9/lib/python3.9/site-packages/urllib3/connectionpool.py", line 783, in urlopen
    return self.urlopen(
  File "/Library/Frameworks/Python.framework/Versions/3.9/lib/python3.9/site-packages/urllib3/connectionpool.py", line 783, in urlopen
    return self.urlopen(
  File "/Library/Frameworks/Python.framework/Versions/3.9/lib/python3.9/site-packages/urllib3/connectionpool.py", line 755, in urlopen
    retries = retries.increment(
  File "/Library/Frameworks/Python.framework/Versions/3.9/lib/python3.9/site-packages/urllib3/util/retry.py", line 574, in increment
    raise MaxRetryError(_pool, url, error or ResponseError(cause))
urllib3.exceptions.MaxRetryError: HTTPConnectionPool(host='localhost', port=63523): Max retries exceeded with url: /session/c57442b967fbcf49e513a96fb69780d5/url (Caused by NewConnectionError('<urllib3.connection.HTTPConnection object at 0x1076ce940>: Failed to establish a new connection: [Errno 61] Connection refused'))

Traceback (most recent call last):
  File "/Library/Frameworks/Python.framework/Versions/3.9/lib/python3.9/site-packages/urllib3/connection.py", line 174, in _new_conn
    conn = connection.create_connection(
  File "/Library/Frameworks/Python.framework/Versions/3.9/lib/python3.9/site-packages/urllib3/util/connection.py", line 96, in create_connection
    raise err
  File "/Library/Frameworks/Python.framework/Versions/3.9/lib/python3.9/site-packages/urllib3/util/connection.py", line 86, in create_connection
    sock.connect(sa)
ConnectionRefusedError: [Errno 61] Connection refused

During handling of the above exception, another exception occurred:

Traceback (most recent call last):
  File "/Library/Frameworks/Python.framework/Versions/3.9/lib/python3.9/site-packages/urllib3/connectionpool.py", line 699, in urlopen
    httplib_response = self._make_request(
  File "/Library/Frameworks/Python.framework/Versions/3.9/lib/python3.9/site-packages/urllib3/connectionpool.py", line 394, in _make_request
    conn.request(method, url, **httplib_request_kw)
  File "/Library/Frameworks/Python.framework/Versions/3.9/lib/python3.9/site-packages/urllib3/connection.py", line 239, in request
    super(HTTPConnection, self).request(method, url, body=body, headers=headers)
  File "/Library/Frameworks/Python.framework/Versions/3.9/lib/python3.9/http/client.py", line 1285, in request
    self._send_request(method, url, body, headers, encode_chunked)
  File "/Library/Frameworks/Python.framework/Versions/3.9/lib/python3.9/http/client.py", line 1331, in _send_request
    self.endheaders(body, encode_chunked=encode_chunked)
  File "/Library/Frameworks/Python.framework/Versions/3.9/lib/python3.9/http/client.py", line 1280, in endheaders
    self._send_output(message_body, encode_chunked=encode_chunked)
  File "/Library/Frameworks/Python.framework/Versions/3.9/lib/python3.9/http/client.py", line 1040, in _send_output
    self.send(msg)
  File "/Library/Frameworks/Python.framework/Versions/3.9/lib/python3.9/http/client.py", line 980, in send
    self.connect()
  File "/Library/Frameworks/Python.framework/Versions/3.9/lib/python3.9/site-packages/urllib3/connection.py", line 205, in connect
    conn = self._new_conn()
  File "/Library/Frameworks/Python.framework/Versions/3.9/lib/python3.9/site-packages/urllib3/connection.py", line 186, in _new_conn
    raise NewConnectionError(
urllib3.exceptions.NewConnectionError: <urllib3.connection.HTTPConnection object at 0x102e364c0>: Failed to establish a new connection: [Errno 61] Connection refused

During handling of the above exception, another exception occurred:

Traceback (most recent call last):
  File "/Users/nathanrush/feast-monorepo/backend/Cart.py", line 186, in _add_ingredient
    added_ingredient = self._add_ingredient_on_page(ingredient_link.link, ingredient)
  File "/Users/nathanrush/feast-monorepo/backend/Cart.py", line 259, in _add_ingredient_on_page
    self.driver.get(link)
  File "/Library/Frameworks/Python.framework/Versions/3.9/lib/python3.9/site-packages/selenium/webdriver/remote/webdriver.py", line 436, in get
    self.execute(Command.GET, {'url': url})
  File "/Library/Frameworks/Python.framework/Versions/3.9/lib/python3.9/site-packages/selenium/webdriver/remote/webdriver.py", line 422, in execute
    response = self.command_executor.execute(driver_command, params)
  File "/Library/Frameworks/Python.framework/Versions/3.9/lib/python3.9/site-packages/selenium/webdriver/remote/remote_connection.py", line 421, in execute
    return self._request(command_info[0], url, body=data)
  File "/Library/Frameworks/Python.framework/Versions/3.9/lib/python3.9/site-packages/selenium/webdriver/remote/remote_connection.py", line 443, in _request
    resp = self._conn.request(method, url, body=body, headers=headers)
  File "/Library/Frameworks/Python.framework/Versions/3.9/lib/python3.9/site-packages/urllib3/request.py", line 78, in request
    return self.request_encode_body(
  File "/Library/Frameworks/Python.framework/Versions/3.9/lib/python3.9/site-packages/urllib3/request.py", line 170, in request_encode_body
    return self.urlopen(method, url, **extra_kw)
  File "/Library/Frameworks/Python.framework/Versions/3.9/lib/python3.9/site-packages/urllib3/poolmanager.py", line 375, in urlopen
    response = conn.urlopen(method, u.request_uri, **kw)
  File "/Library/Frameworks/Python.framework/Versions/3.9/lib/python3.9/site-packages/urllib3/connectionpool.py", line 783, in urlopen
    return self.urlopen(
  File "/Library/Frameworks/Python.framework/Versions/3.9/lib/python3.9/site-packages/urllib3/connectionpool.py", line 783, in urlopen
    return self.urlopen(
  File "/Library/Frameworks/Python.framework/Versions/3.9/lib/python3.9/site-packages/urllib3/connectionpool.py", line 783, in urlopen
    return self.urlopen(
  File "/Library/Frameworks/Python.framework/Versions/3.9/lib/python3.9/site-packages/urllib3/connectionpool.py", line 755, in urlopen
    retries = retries.increment(
  File "/Library/Frameworks/Python.framework/Versions/3.9/lib/python3.9/site-packages/urllib3/util/retry.py", line 574, in increment
    raise MaxRetryError(_pool, url, error or ResponseError(cause))
urllib3.exceptions.MaxRetryError: HTTPConnectionPool(host='localhost', port=63523): Max retries exceeded with url: /session/c57442b967fbcf49e513a96fb69780d5/url (Caused by NewConnectionError('<urllib3.connection.HTTPConnection object at 0x102e364c0>: Failed to establish a new connection: [Errno 61] Connection refused'))

Traceback (most recent call last):
  File "/Library/Frameworks/Python.framework/Versions/3.9/lib/python3.9/site-packages/urllib3/connection.py", line 174, in _new_conn
    conn = connection.create_connection(
  File "/Library/Frameworks/Python.framework/Versions/3.9/lib/python3.9/site-packages/urllib3/util/connection.py", line 96, in create_connection
    raise err
  File "/Library/Frameworks/Python.framework/Versions/3.9/lib/python3.9/site-packages/urllib3/util/connection.py", line 86, in create_connection
    sock.connect(sa)
ConnectionRefusedError: [Errno 61] Connection refused

During handling of the above exception, another exception occurred:

Traceback (most recent call last):
  File "/Library/Frameworks/Python.framework/Versions/3.9/lib/python3.9/site-packages/urllib3/connectionpool.py", line 699, in urlopen
    httplib_response = self._make_request(
  File "/Library/Frameworks/Python.framework/Versions/3.9/lib/python3.9/site-packages/urllib3/connectionpool.py", line 394, in _make_request
    conn.request(method, url, **httplib_request_kw)
  File "/Library/Frameworks/Python.framework/Versions/3.9/lib/python3.9/site-packages/urllib3/connection.py", line 239, in request
    super(HTTPConnection, self).request(method, url, body=body, headers=headers)
  File "/Library/Frameworks/Python.framework/Versions/3.9/lib/python3.9/http/client.py", line 1285, in request
    self._send_request(method, url, body, headers, encode_chunked)
  File "/Library/Frameworks/Python.framework/Versions/3.9/lib/python3.9/http/client.py", line 1331, in _send_request
    self.endheaders(body, encode_chunked=encode_chunked)
  File "/Library/Frameworks/Python.framework/Versions/3.9/lib/python3.9/http/client.py", line 1280, in endheaders
    self._send_output(message_body, encode_chunked=encode_chunked)
  File "/Library/Frameworks/Python.framework/Versions/3.9/lib/python3.9/http/client.py", line 1040, in _send_output
    self.send(msg)
  File "/Library/Frameworks/Python.framework/Versions/3.9/lib/python3.9/http/client.py", line 980, in send
    self.connect()
  File "/Library/Frameworks/Python.framework/Versions/3.9/lib/python3.9/site-packages/urllib3/connection.py", line 205, in connect
    conn = self._new_conn()
  File "/Library/Frameworks/Python.framework/Versions/3.9/lib/python3.9/site-packages/urllib3/connection.py", line 186, in _new_conn
    raise NewConnectionError(
urllib3.exceptions.NewConnectionError: <urllib3.connection.HTTPConnection object at 0x102e334f0>: Failed to establish a new connection: [Errno 61] Connection refused

During handling of the above exception, another exception occurred:

Traceback (most recent call last):
  File "/Users/nathanrush/feast-monorepo/backend/Cart.py", line 186, in _add_ingredient
    added_ingredient = self._add_ingredient_on_page(ingredient_link.link, ingredient)
  File "/Users/nathanrush/feast-monorepo/backend/Cart.py", line 259, in _add_ingredient_on_page
    self.driver.get(link)
  File "/Library/Frameworks/Python.framework/Versions/3.9/lib/python3.9/site-packages/selenium/webdriver/remote/webdriver.py", line 436, in get
    self.execute(Command.GET, {'url': url})
  File "/Library/Frameworks/Python.framework/Versions/3.9/lib/python3.9/site-packages/selenium/webdriver/remote/webdriver.py", line 422, in execute
    response = self.command_executor.execute(driver_command, params)
  File "/Library/Frameworks/Python.framework/Versions/3.9/lib/python3.9/site-packages/selenium/webdriver/remote/remote_connection.py", line 421, in execute
    return self._request(command_info[0], url, body=data)
  File "/Library/Frameworks/Python.framework/Versions/3.9/lib/python3.9/site-packages/selenium/webdriver/remote/remote_connection.py", line 443, in _request
    resp = self._conn.request(method, url, body=body, headers=headers)
  File "/Library/Frameworks/Python.framework/Versions/3.9/lib/python3.9/site-packages/urllib3/request.py", line 78, in request
    return self.request_encode_body(
  File "/Library/Frameworks/Python.framework/Versions/3.9/lib/python3.9/site-packages/urllib3/request.py", line 170, in request_encode_body
    return self.urlopen(method, url, **extra_kw)
  File "/Library/Frameworks/Python.framework/Versions/3.9/lib/python3.9/site-packages/urllib3/poolmanager.py", line 375, in urlopen
    response = conn.urlopen(method, u.request_uri, **kw)
  File "/Library/Frameworks/Python.framework/Versions/3.9/lib/python3.9/site-packages/urllib3/connectionpool.py", line 783, in urlopen
    return self.urlopen(
  File "/Library/Frameworks/Python.framework/Versions/3.9/lib/python3.9/site-packages/urllib3/connectionpool.py", line 783, in urlopen
    return self.urlopen(
  File "/Library/Frameworks/Python.framework/Versions/3.9/lib/python3.9/site-packages/urllib3/connectionpool.py", line 783, in urlopen
    return self.urlopen(
  File "/Library/Frameworks/Python.framework/Versions/3.9/lib/python3.9/site-packages/urllib3/connectionpool.py", line 755, in urlopen
    retries = retries.increment(
  File "/Library/Frameworks/Python.framework/Versions/3.9/lib/python3.9/site-packages/urllib3/util/retry.py", line 574, in increment
    raise MaxRetryError(_pool, url, error or ResponseError(cause))
urllib3.exceptions.MaxRetryError: HTTPConnectionPool(host='localhost', port=63523): Max retries exceeded with url: /session/c57442b967fbcf49e513a96fb69780d5/url (Caused by NewConnectionError('<urllib3.connection.HTTPConnection object at 0x102e334f0>: Failed to establish a new connection: [Errno 61] Connection refused'))

Traceback (most recent call last):
  File "/Library/Frameworks/Python.framework/Versions/3.9/lib/python3.9/site-packages/urllib3/connection.py", line 174, in _new_conn
    conn = connection.create_connection(
  File "/Library/Frameworks/Python.framework/Versions/3.9/lib/python3.9/site-packages/urllib3/util/connection.py", line 96, in create_connection
    raise err
  File "/Library/Frameworks/Python.framework/Versions/3.9/lib/python3.9/site-packages/urllib3/util/connection.py", line 86, in create_connection
    sock.connect(sa)
ConnectionRefusedError: [Errno 61] Connection refused

During handling of the above exception, another exception occurred:

Traceback (most recent call last):
  File "/Library/Frameworks/Python.framework/Versions/3.9/lib/python3.9/site-packages/urllib3/connectionpool.py", line 699, in urlopen
    httplib_response = self._make_request(
  File "/Library/Frameworks/Python.framework/Versions/3.9/lib/python3.9/site-packages/urllib3/connectionpool.py", line 394, in _make_request
    conn.request(method, url, **httplib_request_kw)
  File "/Library/Frameworks/Python.framework/Versions/3.9/lib/python3.9/site-packages/urllib3/connection.py", line 239, in request
    super(HTTPConnection, self).request(method, url, body=body, headers=headers)
  File "/Library/Frameworks/Python.framework/Versions/3.9/lib/python3.9/http/client.py", line 1285, in request
    self._send_request(method, url, body, headers, encode_chunked)
  File "/Library/Frameworks/Python.framework/Versions/3.9/lib/python3.9/http/client.py", line 1331, in _send_request
    self.endheaders(body, encode_chunked=encode_chunked)
  File "/Library/Frameworks/Python.framework/Versions/3.9/lib/python3.9/http/client.py", line 1280, in endheaders
    self._send_output(message_body, encode_chunked=encode_chunked)
  File "/Library/Frameworks/Python.framework/Versions/3.9/lib/python3.9/http/client.py", line 1040, in _send_output
    self.send(msg)
  File "/Library/Frameworks/Python.framework/Versions/3.9/lib/python3.9/http/client.py", line 980, in send
    self.connect()
  File "/Library/Frameworks/Python.framework/Versions/3.9/lib/python3.9/site-packages/urllib3/connection.py", line 205, in connect
    conn = self._new_conn()
  File "/Library/Frameworks/Python.framework/Versions/3.9/lib/python3.9/site-packages/urllib3/connection.py", line 186, in _new_conn
    raise NewConnectionError(
urllib3.exceptions.NewConnectionError: <urllib3.connection.HTTPConnection object at 0x102e322b0>: Failed to establish a new connection: [Errno 61] Connection refused

During handling of the above exception, another exception occurred:

Traceback (most recent call last):
  File "/Users/nathanrush/feast-monorepo/backend/Cart.py", line 186, in _add_ingredient
    added_ingredient = self._add_ingredient_on_page(ingredient_link.link, ingredient)
  File "/Users/nathanrush/feast-monorepo/backend/Cart.py", line 259, in _add_ingredient_on_page
    self.driver.get(link)
  File "/Library/Frameworks/Python.framework/Versions/3.9/lib/python3.9/site-packages/selenium/webdriver/remote/webdriver.py", line 436, in get
    self.execute(Command.GET, {'url': url})
  File "/Library/Frameworks/Python.framework/Versions/3.9/lib/python3.9/site-packages/selenium/webdriver/remote/webdriver.py", line 422, in execute
    response = self.command_executor.execute(driver_command, params)
  File "/Library/Frameworks/Python.framework/Versions/3.9/lib/python3.9/site-packages/selenium/webdriver/remote/remote_connection.py", line 421, in execute
    return self._request(command_info[0], url, body=data)
  File "/Library/Frameworks/Python.framework/Versions/3.9/lib/python3.9/site-packages/selenium/webdriver/remote/remote_connection.py", line 443, in _request
    resp = self._conn.request(method, url, body=body, headers=headers)
  File "/Library/Frameworks/Python.framework/Versions/3.9/lib/python3.9/site-packages/urllib3/request.py", line 78, in request
    return self.request_encode_body(
  File "/Library/Frameworks/Python.framework/Versions/3.9/lib/python3.9/site-packages/urllib3/request.py", line 170, in request_encode_body
    return self.urlopen(method, url, **extra_kw)
  File "/Library/Frameworks/Python.framework/Versions/3.9/lib/python3.9/site-packages/urllib3/poolmanager.py", line 375, in urlopen
    response = conn.urlopen(method, u.request_uri, **kw)
  File "/Library/Frameworks/Python.framework/Versions/3.9/lib/python3.9/site-packages/urllib3/connectionpool.py", line 783, in urlopen
    return self.urlopen(
  File "/Library/Frameworks/Python.framework/Versions/3.9/lib/python3.9/site-packages/urllib3/connectionpool.py", line 783, in urlopen
    return self.urlopen(
  File "/Library/Frameworks/Python.framework/Versions/3.9/lib/python3.9/site-packages/urllib3/connectionpool.py", line 783, in urlopen
    return self.urlopen(
  File "/Library/Frameworks/Python.framework/Versions/3.9/lib/python3.9/site-packages/urllib3/connectionpool.py", line 755, in urlopen
    retries = retries.increment(
  File "/Library/Frameworks/Python.framework/Versions/3.9/lib/python3.9/site-packages/urllib3/util/retry.py", line 574, in increment
    raise MaxRetryError(_pool, url, error or ResponseError(cause))
urllib3.exceptions.MaxRetryError: HTTPConnectionPool(host='localhost', port=63523): Max retries exceeded with url: /session/c57442b967fbcf49e513a96fb69780d5/url (Caused by NewConnectionError('<urllib3.connection.HTTPConnection object at 0x102e322b0>: Failed to establish a new connection: [Errno 61] Connection refused'))

Traceback (most recent call last):
  File "/Library/Frameworks/Python.framework/Versions/3.9/lib/python3.9/site-packages/urllib3/connection.py", line 174, in _new_conn
    conn = connection.create_connection(
  File "/Library/Frameworks/Python.framework/Versions/3.9/lib/python3.9/site-packages/urllib3/util/connection.py", line 96, in create_connection
    raise err
  File "/Library/Frameworks/Python.framework/Versions/3.9/lib/python3.9/site-packages/urllib3/util/connection.py", line 86, in create_connection
    sock.connect(sa)
ConnectionRefusedError: [Errno 61] Connection refused

During handling of the above exception, another exception occurred:

Traceback (most recent call last):
  File "/Library/Frameworks/Python.framework/Versions/3.9/lib/python3.9/site-packages/urllib3/connectionpool.py", line 699, in urlopen
    httplib_response = self._make_request(
  File "/Library/Frameworks/Python.framework/Versions/3.9/lib/python3.9/site-packages/urllib3/connectionpool.py", line 394, in _make_request
    conn.request(method, url, **httplib_request_kw)
  File "/Library/Frameworks/Python.framework/Versions/3.9/lib/python3.9/site-packages/urllib3/connection.py", line 239, in request
    super(HTTPConnection, self).request(method, url, body=body, headers=headers)
  File "/Library/Frameworks/Python.framework/Versions/3.9/lib/python3.9/http/client.py", line 1285, in request
    self._send_request(method, url, body, headers, encode_chunked)
  File "/Library/Frameworks/Python.framework/Versions/3.9/lib/python3.9/http/client.py", line 1331, in _send_request
    self.endheaders(body, encode_chunked=encode_chunked)
  File "/Library/Frameworks/Python.framework/Versions/3.9/lib/python3.9/http/client.py", line 1280, in endheaders
    self._send_output(message_body, encode_chunked=encode_chunked)
  File "/Library/Frameworks/Python.framework/Versions/3.9/lib/python3.9/http/client.py", line 1040, in _send_output
    self.send(msg)
  File "/Library/Frameworks/Python.framework/Versions/3.9/lib/python3.9/http/client.py", line 980, in send
    self.connect()
  File "/Library/Frameworks/Python.framework/Versions/3.9/lib/python3.9/site-packages/urllib3/connection.py", line 205, in connect
    conn = self._new_conn()
  File "/Library/Frameworks/Python.framework/Versions/3.9/lib/python3.9/site-packages/urllib3/connection.py", line 186, in _new_conn
    raise NewConnectionError(
urllib3.exceptions.NewConnectionError: <urllib3.connection.HTTPConnection object at 0x10bcc61c0>: Failed to establish a new connection: [Errno 61] Connection refused

During handling of the above exception, another exception occurred:

Traceback (most recent call last):
  File "/Users/nathanrush/feast-monorepo/backend/Cart.py", line 186, in _add_ingredient
    added_ingredient = self._add_ingredient_on_page(ingredient_link.link, ingredient)
  File "/Users/nathanrush/feast-monorepo/backend/Cart.py", line 259, in _add_ingredient_on_page
    self.driver.get(link)
  File "/Library/Frameworks/Python.framework/Versions/3.9/lib/python3.9/site-packages/selenium/webdriver/remote/webdriver.py", line 436, in get
    self.execute(Command.GET, {'url': url})
  File "/Library/Frameworks/Python.framework/Versions/3.9/lib/python3.9/site-packages/selenium/webdriver/remote/webdriver.py", line 422, in execute
    response = self.command_executor.execute(driver_command, params)
  File "/Library/Frameworks/Python.framework/Versions/3.9/lib/python3.9/site-packages/selenium/webdriver/remote/remote_connection.py", line 421, in execute
    return self._request(command_info[0], url, body=data)
  File "/Library/Frameworks/Python.framework/Versions/3.9/lib/python3.9/site-packages/selenium/webdriver/remote/remote_connection.py", line 443, in _request
    resp = self._conn.request(method, url, body=body, headers=headers)
  File "/Library/Frameworks/Python.framework/Versions/3.9/lib/python3.9/site-packages/urllib3/request.py", line 78, in request
    return self.request_encode_body(
  File "/Library/Frameworks/Python.framework/Versions/3.9/lib/python3.9/site-packages/urllib3/request.py", line 170, in request_encode_body
    return self.urlopen(method, url, **extra_kw)
  File "/Library/Frameworks/Python.framework/Versions/3.9/lib/python3.9/site-packages/urllib3/poolmanager.py", line 375, in urlopen
    response = conn.urlopen(method, u.request_uri, **kw)
  File "/Library/Frameworks/Python.framework/Versions/3.9/lib/python3.9/site-packages/urllib3/connectionpool.py", line 783, in urlopen
    return self.urlopen(
  File "/Library/Frameworks/Python.framework/Versions/3.9/lib/python3.9/site-packages/urllib3/connectionpool.py", line 783, in urlopen
    return self.urlopen(
  File "/Library/Frameworks/Python.framework/Versions/3.9/lib/python3.9/site-packages/urllib3/connectionpool.py", line 783, in urlopen
    return self.urlopen(
  File "/Library/Frameworks/Python.framework/Versions/3.9/lib/python3.9/site-packages/urllib3/connectionpool.py", line 755, in urlopen
    retries = retries.increment(
  File "/Library/Frameworks/Python.framework/Versions/3.9/lib/python3.9/site-packages/urllib3/util/retry.py", line 574, in increment
    raise MaxRetryError(_pool, url, error or ResponseError(cause))
urllib3.exceptions.MaxRetryError: HTTPConnectionPool(host='localhost', port=63523): Max retries exceeded with url: /session/c57442b967fbcf49e513a96fb69780d5/url (Caused by NewConnectionError('<urllib3.connection.HTTPConnection object at 0x10bcc61c0>: Failed to establish a new connection: [Errno 61] Connection refused'))

Traceback (most recent call last):
  File "/Library/Frameworks/Python.framework/Versions/3.9/lib/python3.9/site-packages/urllib3/connection.py", line 174, in _new_conn
    conn = connection.create_connection(
  File "/Library/Frameworks/Python.framework/Versions/3.9/lib/python3.9/site-packages/urllib3/util/connection.py", line 96, in create_connection
    raise err
  File "/Library/Frameworks/Python.framework/Versions/3.9/lib/python3.9/site-packages/urllib3/util/connection.py", line 86, in create_connection
    sock.connect(sa)
ConnectionRefusedError: [Errno 61] Connection refused

During handling of the above exception, another exception occurred:

Traceback (most recent call last):
  File "/Library/Frameworks/Python.framework/Versions/3.9/lib/python3.9/site-packages/urllib3/connectionpool.py", line 699, in urlopen
    httplib_response = self._make_request(
  File "/Library/Frameworks/Python.framework/Versions/3.9/lib/python3.9/site-packages/urllib3/connectionpool.py", line 394, in _make_request
    conn.request(method, url, **httplib_request_kw)
  File "/Library/Frameworks/Python.framework/Versions/3.9/lib/python3.9/site-packages/urllib3/connection.py", line 239, in request
    super(HTTPConnection, self).request(method, url, body=body, headers=headers)
  File "/Library/Frameworks/Python.framework/Versions/3.9/lib/python3.9/http/client.py", line 1285, in request
    self._send_request(method, url, body, headers, encode_chunked)
  File "/Library/Frameworks/Python.framework/Versions/3.9/lib/python3.9/http/client.py", line 1331, in _send_request
    self.endheaders(body, encode_chunked=encode_chunked)
  File "/Library/Frameworks/Python.framework/Versions/3.9/lib/python3.9/http/client.py", line 1280, in endheaders
    self._send_output(message_body, encode_chunked=encode_chunked)
  File "/Library/Frameworks/Python.framework/Versions/3.9/lib/python3.9/http/client.py", line 1040, in _send_output
    self.send(msg)
  File "/Library/Frameworks/Python.framework/Versions/3.9/lib/python3.9/http/client.py", line 980, in send
    self.connect()
  File "/Library/Frameworks/Python.framework/Versions/3.9/lib/python3.9/site-packages/urllib3/connection.py", line 205, in connect
    conn = self._new_conn()
  File "/Library/Frameworks/Python.framework/Versions/3.9/lib/python3.9/site-packages/urllib3/connection.py", line 186, in _new_conn
    raise NewConnectionError(
urllib3.exceptions.NewConnectionError: <urllib3.connection.HTTPConnection object at 0x102e3a190>: Failed to establish a new connection: [Errno 61] Connection refused

During handling of the above exception, another exception occurred:

Traceback (most recent call last):
  File "/Users/nathanrush/feast-monorepo/backend/Cart.py", line 186, in _add_ingredient
    added_ingredient = self._add_ingredient_on_page(ingredient_link.link, ingredient)
  File "/Users/nathanrush/feast-monorepo/backend/Cart.py", line 259, in _add_ingredient_on_page
    self.driver.get(link)
  File "/Library/Frameworks/Python.framework/Versions/3.9/lib/python3.9/site-packages/selenium/webdriver/remote/webdriver.py", line 436, in get
    self.execute(Command.GET, {'url': url})
  File "/Library/Frameworks/Python.framework/Versions/3.9/lib/python3.9/site-packages/selenium/webdriver/remote/webdriver.py", line 422, in execute
    response = self.command_executor.execute(driver_command, params)
  File "/Library/Frameworks/Python.framework/Versions/3.9/lib/python3.9/site-packages/selenium/webdriver/remote/remote_connection.py", line 421, in execute
    return self._request(command_info[0], url, body=data)
  File "/Library/Frameworks/Python.framework/Versions/3.9/lib/python3.9/site-packages/selenium/webdriver/remote/remote_connection.py", line 443, in _request
    resp = self._conn.request(method, url, body=body, headers=headers)
  File "/Library/Frameworks/Python.framework/Versions/3.9/lib/python3.9/site-packages/urllib3/request.py", line 78, in request
    return self.request_encode_body(
  File "/Library/Frameworks/Python.framework/Versions/3.9/lib/python3.9/site-packages/urllib3/request.py", line 170, in request_encode_body
    return self.urlopen(method, url, **extra_kw)
  File "/Library/Frameworks/Python.framework/Versions/3.9/lib/python3.9/site-packages/urllib3/poolmanager.py", line 375, in urlopen
    response = conn.urlopen(method, u.request_uri, **kw)
  File "/Library/Frameworks/Python.framework/Versions/3.9/lib/python3.9/site-packages/urllib3/connectionpool.py", line 783, in urlopen
    return self.urlopen(
  File "/Library/Frameworks/Python.framework/Versions/3.9/lib/python3.9/site-packages/urllib3/connectionpool.py", line 783, in urlopen
    return self.urlopen(
  File "/Library/Frameworks/Python.framework/Versions/3.9/lib/python3.9/site-packages/urllib3/connectionpool.py", line 783, in urlopen
    return self.urlopen(
  File "/Library/Frameworks/Python.framework/Versions/3.9/lib/python3.9/site-packages/urllib3/connectionpool.py", line 755, in urlopen
    retries = retries.increment(
  File "/Library/Frameworks/Python.framework/Versions/3.9/lib/python3.9/site-packages/urllib3/util/retry.py", line 574, in increment
    raise MaxRetryError(_pool, url, error or ResponseError(cause))
urllib3.exceptions.MaxRetryError: HTTPConnectionPool(host='localhost', port=63523): Max retries exceeded with url: /session/c57442b967fbcf49e513a96fb69780d5/url (Caused by NewConnectionError('<urllib3.connection.HTTPConnection object at 0x102e3a190>: Failed to establish a new connection: [Errno 61] Connection refused'))

Traceback (most recent call last):
  File "/Library/Frameworks/Python.framework/Versions/3.9/lib/python3.9/site-packages/urllib3/connection.py", line 174, in _new_conn
    conn = connection.create_connection(
  File "/Library/Frameworks/Python.framework/Versions/3.9/lib/python3.9/site-packages/urllib3/util/connection.py", line 96, in create_connection
    raise err
  File "/Library/Frameworks/Python.framework/Versions/3.9/lib/python3.9/site-packages/urllib3/util/connection.py", line 86, in create_connection
    sock.connect(sa)
ConnectionRefusedError: [Errno 61] Connection refused

During handling of the above exception, another exception occurred:

Traceback (most recent call last):
  File "/Library/Frameworks/Python.framework/Versions/3.9/lib/python3.9/site-packages/urllib3/connectionpool.py", line 699, in urlopen
    httplib_response = self._make_request(
  File "/Library/Frameworks/Python.framework/Versions/3.9/lib/python3.9/site-packages/urllib3/connectionpool.py", line 394, in _make_request
    conn.request(method, url, **httplib_request_kw)
  File "/Library/Frameworks/Python.framework/Versions/3.9/lib/python3.9/site-packages/urllib3/connection.py", line 239, in request
    super(HTTPConnection, self).request(method, url, body=body, headers=headers)
  File "/Library/Frameworks/Python.framework/Versions/3.9/lib/python3.9/http/client.py", line 1285, in request
    self._send_request(method, url, body, headers, encode_chunked)
  File "/Library/Frameworks/Python.framework/Versions/3.9/lib/python3.9/http/client.py", line 1331, in _send_request
    self.endheaders(body, encode_chunked=encode_chunked)
  File "/Library/Frameworks/Python.framework/Versions/3.9/lib/python3.9/http/client.py", line 1280, in endheaders
    self._send_output(message_body, encode_chunked=encode_chunked)
  File "/Library/Frameworks/Python.framework/Versions/3.9/lib/python3.9/http/client.py", line 1040, in _send_output
    self.send(msg)
  File "/Library/Frameworks/Python.framework/Versions/3.9/lib/python3.9/http/client.py", line 980, in send
    self.connect()
  File "/Library/Frameworks/Python.framework/Versions/3.9/lib/python3.9/site-packages/urllib3/connection.py", line 205, in connect
    conn = self._new_conn()
  File "/Library/Frameworks/Python.framework/Versions/3.9/lib/python3.9/site-packages/urllib3/connection.py", line 186, in _new_conn
    raise NewConnectionError(
urllib3.exceptions.NewConnectionError: <urllib3.connection.HTTPConnection object at 0x10ba40c70>: Failed to establish a new connection: [Errno 61] Connection refused

During handling of the above exception, another exception occurred:

Traceback (most recent call last):
  File "/Users/nathanrush/feast-monorepo/backend/Cart.py", line 186, in _add_ingredient
    added_ingredient = self._add_ingredient_on_page(ingredient_link.link, ingredient)
  File "/Users/nathanrush/feast-monorepo/backend/Cart.py", line 259, in _add_ingredient_on_page
    self.driver.get(link)
  File "/Library/Frameworks/Python.framework/Versions/3.9/lib/python3.9/site-packages/selenium/webdriver/remote/webdriver.py", line 436, in get
    self.execute(Command.GET, {'url': url})
  File "/Library/Frameworks/Python.framework/Versions/3.9/lib/python3.9/site-packages/selenium/webdriver/remote/webdriver.py", line 422, in execute
    response = self.command_executor.execute(driver_command, params)
  File "/Library/Frameworks/Python.framework/Versions/3.9/lib/python3.9/site-packages/selenium/webdriver/remote/remote_connection.py", line 421, in execute
    return self._request(command_info[0], url, body=data)
  File "/Library/Frameworks/Python.framework/Versions/3.9/lib/python3.9/site-packages/selenium/webdriver/remote/remote_connection.py", line 443, in _request
    resp = self._conn.request(method, url, body=body, headers=headers)
  File "/Library/Frameworks/Python.framework/Versions/3.9/lib/python3.9/site-packages/urllib3/request.py", line 78, in request
    return self.request_encode_body(
  File "/Library/Frameworks/Python.framework/Versions/3.9/lib/python3.9/site-packages/urllib3/request.py", line 170, in request_encode_body
    return self.urlopen(method, url, **extra_kw)
  File "/Library/Frameworks/Python.framework/Versions/3.9/lib/python3.9/site-packages/urllib3/poolmanager.py", line 375, in urlopen
    response = conn.urlopen(method, u.request_uri, **kw)
  File "/Library/Frameworks/Python.framework/Versions/3.9/lib/python3.9/site-packages/urllib3/connectionpool.py", line 783, in urlopen
    return self.urlopen(
  File "/Library/Frameworks/Python.framework/Versions/3.9/lib/python3.9/site-packages/urllib3/connectionpool.py", line 783, in urlopen
    return self.urlopen(
  File "/Library/Frameworks/Python.framework/Versions/3.9/lib/python3.9/site-packages/urllib3/connectionpool.py", line 783, in urlopen
    return self.urlopen(
  File "/Library/Frameworks/Python.framework/Versions/3.9/lib/python3.9/site-packages/urllib3/connectionpool.py", line 755, in urlopen
    retries = retries.increment(
  File "/Library/Frameworks/Python.framework/Versions/3.9/lib/python3.9/site-packages/urllib3/util/retry.py", line 574, in increment
    raise MaxRetryError(_pool, url, error or ResponseError(cause))
urllib3.exceptions.MaxRetryError: HTTPConnectionPool(host='localhost', port=63523): Max retries exceeded with url: /session/c57442b967fbcf49e513a96fb69780d5/url (Caused by NewConnectionError('<urllib3.connection.HTTPConnection object at 0x10ba40c70>: Failed to establish a new connection: [Errno 61] Connection refused'))

Traceback (most recent call last):
  File "/Library/Frameworks/Python.framework/Versions/3.9/lib/python3.9/site-packages/urllib3/connection.py", line 174, in _new_conn
    conn = connection.create_connection(
  File "/Library/Frameworks/Python.framework/Versions/3.9/lib/python3.9/site-packages/urllib3/util/connection.py", line 96, in create_connection
    raise err
  File "/Library/Frameworks/Python.framework/Versions/3.9/lib/python3.9/site-packages/urllib3/util/connection.py", line 86, in create_connection
    sock.connect(sa)
ConnectionRefusedError: [Errno 61] Connection refused

During handling of the above exception, another exception occurred:

Traceback (most recent call last):
  File "/Library/Frameworks/Python.framework/Versions/3.9/lib/python3.9/site-packages/urllib3/connectionpool.py", line 699, in urlopen
    httplib_response = self._make_request(
  File "/Library/Frameworks/Python.framework/Versions/3.9/lib/python3.9/site-packages/urllib3/connectionpool.py", line 394, in _make_request
    conn.request(method, url, **httplib_request_kw)
  File "/Library/Frameworks/Python.framework/Versions/3.9/lib/python3.9/site-packages/urllib3/connection.py", line 239, in request
    super(HTTPConnection, self).request(method, url, body=body, headers=headers)
  File "/Library/Frameworks/Python.framework/Versions/3.9/lib/python3.9/http/client.py", line 1285, in request
    self._send_request(method, url, body, headers, encode_chunked)
  File "/Library/Frameworks/Python.framework/Versions/3.9/lib/python3.9/http/client.py", line 1331, in _send_request
    self.endheaders(body, encode_chunked=encode_chunked)
  File "/Library/Frameworks/Python.framework/Versions/3.9/lib/python3.9/http/client.py", line 1280, in endheaders
    self._send_output(message_body, encode_chunked=encode_chunked)
  File "/Library/Frameworks/Python.framework/Versions/3.9/lib/python3.9/http/client.py", line 1040, in _send_output
    self.send(msg)
  File "/Library/Frameworks/Python.framework/Versions/3.9/lib/python3.9/http/client.py", line 980, in send
    self.connect()
  File "/Library/Frameworks/Python.framework/Versions/3.9/lib/python3.9/site-packages/urllib3/connection.py", line 205, in connect
    conn = self._new_conn()
  File "/Library/Frameworks/Python.framework/Versions/3.9/lib/python3.9/site-packages/urllib3/connection.py", line 186, in _new_conn
    raise NewConnectionError(
urllib3.exceptions.NewConnectionError: <urllib3.connection.HTTPConnection object at 0x102e34f40>: Failed to establish a new connection: [Errno 61] Connection refused

During handling of the above exception, another exception occurred:

Traceback (most recent call last):
  File "/Users/nathanrush/feast-monorepo/backend/Cart.py", line 186, in _add_ingredient
    added_ingredient = self._add_ingredient_on_page(ingredient_link.link, ingredient)
  File "/Users/nathanrush/feast-monorepo/backend/Cart.py", line 259, in _add_ingredient_on_page
    self.driver.get(link)
  File "/Library/Frameworks/Python.framework/Versions/3.9/lib/python3.9/site-packages/selenium/webdriver/remote/webdriver.py", line 436, in get
    self.execute(Command.GET, {'url': url})
  File "/Library/Frameworks/Python.framework/Versions/3.9/lib/python3.9/site-packages/selenium/webdriver/remote/webdriver.py", line 422, in execute
    response = self.command_executor.execute(driver_command, params)
  File "/Library/Frameworks/Python.framework/Versions/3.9/lib/python3.9/site-packages/selenium/webdriver/remote/remote_connection.py", line 421, in execute
    return self._request(command_info[0], url, body=data)
  File "/Library/Frameworks/Python.framework/Versions/3.9/lib/python3.9/site-packages/selenium/webdriver/remote/remote_connection.py", line 443, in _request
    resp = self._conn.request(method, url, body=body, headers=headers)
  File "/Library/Frameworks/Python.framework/Versions/3.9/lib/python3.9/site-packages/urllib3/request.py", line 78, in request
    return self.request_encode_body(
  File "/Library/Frameworks/Python.framework/Versions/3.9/lib/python3.9/site-packages/urllib3/request.py", line 170, in request_encode_body
    return self.urlopen(method, url, **extra_kw)
  File "/Library/Frameworks/Python.framework/Versions/3.9/lib/python3.9/site-packages/urllib3/poolmanager.py", line 375, in urlopen
    response = conn.urlopen(method, u.request_uri, **kw)
  File "/Library/Frameworks/Python.framework/Versions/3.9/lib/python3.9/site-packages/urllib3/connectionpool.py", line 783, in urlopen
    return self.urlopen(
  File "/Library/Frameworks/Python.framework/Versions/3.9/lib/python3.9/site-packages/urllib3/connectionpool.py", line 783, in urlopen
    return self.urlopen(
  File "/Library/Frameworks/Python.framework/Versions/3.9/lib/python3.9/site-packages/urllib3/connectionpool.py", line 783, in urlopen
    return self.urlopen(
  File "/Library/Frameworks/Python.framework/Versions/3.9/lib/python3.9/site-packages/urllib3/connectionpool.py", line 755, in urlopen
    retries = retries.increment(
  File "/Library/Frameworks/Python.framework/Versions/3.9/lib/python3.9/site-packages/urllib3/util/retry.py", line 574, in increment
    raise MaxRetryError(_pool, url, error or ResponseError(cause))
urllib3.exceptions.MaxRetryError: HTTPConnectionPool(host='localhost', port=63523): Max retries exceeded with url: /session/c57442b967fbcf49e513a96fb69780d5/url (Caused by NewConnectionError('<urllib3.connection.HTTPConnection object at 0x102e34f40>: Failed to establish a new connection: [Errno 61] Connection refused'))

